Workbook
Name Slicer_5_FACTOR: #N/A
Name Slicer_CATEGORY: #N/A
Name Slicer_PARAMETER: #N/A
Name Slicer_PARAMETER1: #N/A
Name Slicer_PIC: #N/A

Sheet Activity Plan
B1: IMPROVEMENT DOZER CAM — PROJECT DEVELOPMENT PLAN | S1: PROJECT START | U1: BULAN | W1: TAHUN | Y1: DURASI (D)
U2: JUNI | W2: 2026 | Y2: 90 | AD2: COMPLETE | AH2: STILL PROGRESS | DI2: UNDER TARGET (Actual < Plan) | DO2: DELAY / GAP / KETERLAMBATAN | DV2: PROGRESS ON SCHEDULE | EB2: COMPLETED ON PLAN | EG2: AHEAD OF SCHEDULE | EO2: < 80% | ER2: > 80% & < 90% | EV2: > 90% & < 95% | EZ2: > 95% & < 100% | FD2: > 100%
S3: =DATE($W$2, MATCH($U$2,{"JANUARI";"FEBRUARI";"MARET";"APRIL";"MEI";"JUNI";"JULI";"AGUSTUS";"SEPTEMBER";"OKTOBER";"NOVEMBER";"DESEMBER"},0), 1 + COLUMN(A1) - 1) -> 46174
B4: TEMA : MENINGKATKAN PHYSICAL AVAILABILITY (PA) LIGHT VEHICLE (LV)
B5: JUDUL : MENURUNKAN BREAKDOWN UNSCHEDULE LV | S5: PLAN | DG5: ACTUAL | GU5: ACHIVE
H6: PLAN | K6: ACTUAL | S6: =IF(DAY(S7)=1,TEXT(S7,"mmm yyyy"),"") -> Jun 2026 | T6: =IF(DAY(T7)=1,TEXT(T7,"mmm yyyy"),"") | U6: =IF(DAY(U7)=1,TEXT(U7,"mmm yyyy"),"") | V6: =IF(DAY(V7)=1,TEXT(V7,"mmm yyyy"),"") | W6: =IF(DAY(W7)=1,TEXT(W7,"mmm yyyy"),"") | X6: =IF(DAY(X7)=1,TEXT(X7,"mmm yyyy"),"") | Y6: =IF(DAY(Y7)=1,TEXT(Y7,"mmm yyyy"),"") | Z6: =IF(DAY(Z7)=1,TEXT(Z7,"mmm yyyy"),"") | ... DE6: =IF(DAY(DE7)=1,TEXT(DE7,"mmm yyyy"),"") | DG6: =IF(DAY(DG7)=1,TEXT(DG7,"mmm yyyy"),"") -> Jun 2026 | DH6: =IF(DAY(DH7)=1,TEXT(DH7,"mmm yyyy"),"") | DI6: =IF(DAY(DI7)=1,TEXT(DI7,"mmm yyyy"),"") | DJ6: =IF(DAY(DJ7)=1,TEXT(DJ7,"mmm yyyy"),"") | DK6: =IF(DAY(DK7)=1,TEXT(DK7,"mmm yyyy"),"") | DL6: =IF(DAY(DL7)=1,TEXT(DL7,"mmm yyyy"),"") | DM6: =IF(DAY(DM7)=1,TEXT(DM7,"mmm yyyy"),"") | DN6: =IF(DAY(DN7)=1,TEXT(DN7,"mmm yyyy"),"") | ... GS6: =IF(DAY(GS7)=1,TEXT(GS7,"mmm yyyy"),"") | GU6: =IF(DAY(GU7)=1,TEXT(GU7,"mmm yyyy"),"") -> Jun 2026 | GV6: =IF(DAY(GV7)=1,TEXT(GV7,"mmm yyyy"),"") | GW6: =IF(DAY(GW7)=1,TEXT(GW7,"mmm yyyy"),"") | GX6: =IF(DAY(GX7)=1,TEXT(GX7,"mmm yyyy"),"") | GY6: =IF(DAY(GY7)=1,TEXT(GY7,"mmm yyyy"),"") | GZ6: =IF(DAY(GZ7)=1,TEXT(GZ7,"mmm yyyy"),"") | HA6: =IF(DAY(HA7)=1,TEXT(HA7,"mmm yyyy"),"") | HB6: =IF(DAY(HB7)=1,TEXT(HB7,"mmm yyyy"),"") | ... KG6: =IF(DAY(KG7)=1,TEXT(KG7,"mmm yyyy"),"")
B7: NO | C7: 5 FACTOR | D7: BRAINSTORMING (PROBLEM) | E7: CATEGORY | F7: ACTION PLAN | G7: PIC | H7: PLAN START | I7: DUE DATA | J7: PLAN DURATION | K7: ACTUAL START | L7: ACTUAL FINISH | M7: ACTUAL DURATION | N7: STATUS | O7: DUE STATUS | P7: COMPLETION | Q7: COMPLETION_FLAG | S7: =S3 -> 46174 | T7: =S7+1 -> 46175 | U7: =T7+1 -> 46176 | V7: =U7+1 -> 46177 | W7: =V7+1 -> 46178 | X7: =W7+1 -> 46179 | Y7: =X7+1 -> 46180 | Z7: =Y7+1 -> 46181 | AA7: =Z7+1 -> 46182 | ... DE7: =DD7+1 -> 46264 | DG7: =S3 -> 46174 | DH7: =DG7+1 -> 46175 | DI7: =DH7+1 -> 46176 | DJ7: =DI7+1 -> 46177 | DK7: =DJ7+1 -> 46178 | DL7: =DK7+1 -> 46179 | DM7: =DL7+1 -> 46180 | DN7: =DM7+1 -> 46181 | DO7: =DN7+1 -> 46182 | ... GS7: =GR7+1 -> 46264 | GU7: =S3 -> 46174 | GV7: =GU7+1 -> 46175 | GW7: =GV7+1 -> 46176 | GX7: =GW7+1 -> 46177 | GY7: =GX7+1 -> 46178 | GZ7: =GY7+1 -> 46179 | HA7: =GZ7+1 -> 46180 | HB7: =HA7+1 -> 46181 | HC7: =HB7+1 -> 46182 | ... KG7: =KF7+1 -> 46264
B8: 1 | C8: MAN | D8: User tetap mengoperasikan LV dengan gejala abnormal karena belum memahami batas aman, tidak ada konsekuensi, dan temuan P2H tidak mendapat feedback. | E8: Quick Action | F8: Lakukan refreshment care unit dan sosialisasi kriteria STOP/GO kepada seluruh user LV. | G8: GS-PLANT-SHE | H8: 46181 | I8: 46192 | J8: =(I8-H8)+1 -> 12 | M8: =IF(AND(K8=0,L8=0),"No Progress",IF(Tbl_SM[[#This Row],[ACTUAL START]]="",0,IF(L8-K8<0,"On Progress",L8-K8))) -> No Progress | N8: =IF(Tbl_SM[[#This Row],[PLAN START]]="","", IF(Tbl_SM[[#This Row],[ACTUAL FINISH]]<>"","CLOSE", IF(Tbl_SM[[#This Row],[ACTUAL START]]<>"","ON PROGRESS", "OPEN"))) -> OPEN | O8: =IF(Tbl_SM[[#This Row],[PLAN START]]="","", IF(Tbl_SM[[#This Row],[ACTUAL FINISH]]<>"","CLOSE", IF(TODAY()>Tbl_SM[[#This Row],[DUE DATA]],"OVERDUE", IF((Tbl_SM[[#This Row],[DUE DATA]]-TODAY())<=3,"< 3 HARI", IF((Tbl_SM[[#This Row],[DUE DATA]]-TODAY())<=7,"< 7 HARI", IF((Tbl_SM[[#This Row],[DUE DATA]]-TODAY())<=14,"< 14 HARI", "> 14 HARI")))))) -> < 14 HARI | P8: =IF(SUM(S8:AW8)=0,"",IFERROR(MAX(DG8:EK8),"")) -> 0.52666667 | Q8: =IF(Tbl_SM[[#This Row],[STATUS]]="CLOSE",1,0) -> 0 | S8: 0.05 | T8: 0.08 | U8: 0.1 | V8: 0.12666667 | W8: 0.15166667 | X8: 0.17666667 | Y8: 0.20166667 | Z8: 0.22666667 | AA8: 0.25166667 | AB8: 0.27666667 | AC8: 0.30166667 | AD8: 0.32666667 | AE8: 0.35166667 | AF8: 0.37666667 | AG8: 0.40166667 | AH8: 0.42666667 | AI8: 0.45166667 | AJ8: 0.47666667 | AK8: 0.50166667 | AL8: 0.50166667 | AM8: 0.50166667 | AN8: 0.50166667 | AO8: 0.50166667 | AP8: 0.50166667 | AQ8: 0.50166667 | AR8: 0.50166667 | AS8: 0.50166667 | AT8: 0.50166667 | AU8: 0.51 | AV8: 0.51833333 | AW8: 0.52666667 | AX8: 0.535 | AY8: 0.54333333 | AZ8: 0.55166667 | BA8: 0.56 | BB8: 0.56833333 | BC8: 0.6 | BD8: 0.63 | BE8: 0.66 | BF8: 0.69 | BG8: 0.72 | BH8: 0.75 | BI8: 0.78 | BJ8: 0.81 | BK8: 0.84 | BL8: 0.87 | BM8: 0.9 | BN8: 0.93 | BO8: 0.96 | BP8: 0.99 | BQ8: 1 | BR8: 1 | BS8: 1 | BT8: 1 | BU8: 1 | BV8: 1 | BW8: 1 | BX8: 1 | BY8: 1 | BZ8: 1 | CA8: 1 | CB8: 1 | CC8: 1 | CD8: 1 | CE8: 1 | CF8: 1 | CG8: 1 | CH8: 1 | CI8: 1 | CJ8: 1 | CK8: 1 | CL8: 1 | CM8: 1 | CN8: 1 | CO8: 1 | CP8: 1 | CQ8: 1 | CR8: 1 | CS8: 1 | CT8: 1 | CU8: 1 | CV8: 1 | CW8: 1 | CX8: 1 | CY8: 1 | CZ8: 1 | DA8: 1 | DB8: 1 | DC8: 1 | DD8: 1 | DE8: 1 | DG8: 0.05 | DH8: 0.08 | DI8: 0.1 | DJ8: 0.12666667 | DK8: 0.15166667 | DL8: 0.17666667 | DM8: 0.20166667 | DN8: 0.22666667 | DO8: 0.25166667 | DP8: 0.27666667 | DQ8: 0.30166667 | DR8: 0.32666667 | DS8: 0.35166667 | DT8: 0.37666667 | DU8: 0.40166667 | DV8: 0.42666667 | DW8: 0.45166667 | DX8: 0.47666667 | DY8: 0.50166667 | DZ8: 0.50166667 | EA8: 0.50166667 | EB8: 0.50166667 | EC8: 0.50166667 | ED8: 0.50166667 | EE8: 0.50166667 | EF8: 0.50166667 | EG8: 0.50166667 | EH8: 0.50166667 | EI8: 0.51 | EJ8: 0.51833333 | EK8: 0.52666667 | EL8: 0.535 | EM8: 0.54333333 | EN8: 0.55166667 | EO8: 0.56 | EP8: 0.56833333 | EQ8: 0.6 | ER8: 0.63 | ES8: 0.66 | ET8: 0.69 | EU8: 0.72 | EV8: 0.75 | EW8: 0.78 | EX8: 0.81 | EY8: 0.84 | EZ8: 0.87 | FA8: 0.9 | FB8: 0.93 | FC8: 0.96 | FD8: 0.99 | FE8: 1 | FF8: 1 | FG8: 1 | FH8: 1 | FI8: 1 | FJ8: 1 | FK8: 1 | FL8: 1 | FM8: 1 | FN8: 1 | FO8: 1 | FP8: 1 | FQ8: 1 | FR8: 1 | FS8: 1 | FT8: 1 | FU8: 1 | FV8: 1 | FW8: 1 | FX8: 1 | FY8: 1 | FZ8: 1 | GA8: 1 | GB8: 1 | GC8: 1 | GD8: 1 | GE8: 1 | GF8: 1 | GG8: 1 | GH8: 1 | GI8: 1 | GJ8: 1 | GK8: 1 | GL8: 1 | GM8: 1 | GN8: 1 | GO8: 1 | GP8: 1 | GQ8: 1 | GR8: 1 | GS8: 1 | GU8: =IF(AND(OR(S8="",S8=0),OR(DG8="",DG8=0)),"", MIN(1.2, IFERROR(DG8/IF(OR(S8="",S8=0),1,S8),0))) -> 1 | GV8: =IF(AND(OR(T8="",T8=0),OR(DH8="",DH8=0)),"", MIN(1.2, IFERROR(DH8/IF(OR(T8="",T8=0),1,T8),0))) -> 1 | GW8: =IF(AND(OR(U8="",U8=0),OR(DI8="",DI8=0)),"", MIN(1.2, IFERROR(DI8/IF(OR(U8="",U8=0),1,U8),0))) -> 1 | GX8: =IF(AND(OR(V8="",V8=0),OR(DJ8="",DJ8=0)),"", MIN(1.2, IFERROR(DJ8/IF(OR(V8="",V8=0),1,V8),0))) -> 1 | GY8: =IF(AND(OR(W8="",W8=0),OR(DK8="",DK8=0)),"", MIN(1.2, IFERROR(DK8/IF(OR(W8="",W8=0),1,W8),0))) -> 1 | GZ8: =IF(AND(OR(X8="",X8=0),OR(DL8="",DL8=0)),"", MIN(1.2, IFERROR(DL8/IF(OR(X8="",X8=0),1,X8),0))) -> 1 | HA8: =IF(AND(OR(Y8="",Y8=0),OR(DM8="",DM8=0)),"", MIN(1.2, IFERROR(DM8/IF(OR(Y8="",Y8=0),1,Y8),0))) -> 1 | HB8: =IF(AND(OR(Z8="",Z8=0),OR(DN8="",DN8=0)),"", MIN(1.2, IFERROR(DN8/IF(OR(Z8="",Z8=0),1,Z8),0))) -> 1 | ... KG8: =IF(AND(OR(DE8="",DE8=0),OR(GS8="",GS8=0)),"", MIN(1.2, IFERROR(GS8/IF(OR(DE8="",DE8=0),1,DE8),0))) -> 1
B9: 2 | C9: MAN | D9: Kepedulian rendah karena tidak ada ownership unit dan kinerja pemeliharaan user tidak diukur. | E9: Long Term / Development | F9: Tetapkan user/PIC tetap per LV, KPI compliance P2H, serta evaluasi bulanan per departemen. | G9: GS-HC-USER | H9: 46188 | I9: 46220 | J9: =(I9-H9)+1 -> 33 | M9: =IF(AND(K9=0,L9=0),"No Progress",IF(Tbl_SM[[#This Row],[ACTUAL START]]="",0,IF(L9-K9<0,"On Progress",L9-K9))) -> No Progress | N9: =IF(Tbl_SM[[#This Row],[PLAN START]]="","", IF(Tbl_SM[[#This Row],[ACTUAL FINISH]]<>"","CLOSE", IF(Tbl_SM[[#This Row],[ACTUAL START]]<>"","ON PROGRESS", "OPEN"))) -> OPEN | O9: =IF(Tbl_SM[[#This Row],[PLAN START]]="","", IF(Tbl_SM[[#This Row],[ACTUAL FINISH]]<>"","CLOSE", IF(TODAY()>Tbl_SM[[#This Row],[DUE DATA]],"OVERDUE", IF((Tbl_SM[[#This Row],[DUE DATA]]-TODAY())<=3,"< 3 HARI", IF((Tbl_SM[[#This Row],[DUE DATA]]-TODAY())<=7,"< 7 HARI", IF((Tbl_SM[[#This Row],[DUE DATA]]-TODAY())<=14,"< 14 HARI", "> 14 HARI")))))) -> > 14 HARI | P9: =IF(SUM(S9:AW9)=0,"",IFERROR(MAX(DG9:EK9),"")) -> 0.52666667 | Q9: =IF(Tbl_SM[[#This Row],[STATUS]]="CLOSE",1,0) -> 0 | S9: 0.05 | T9: 0.08 | U9: 0.1 | V9: 0.12666667 | W9: 0.15166667 | X9: 0.17666667 | Y9: 0.20166667 | Z9: 0.22666667 | AA9: 0.25166667 | AB9: 0.27666667 | AC9: 0.30166667 | AD9: 0.32666667 | AE9: 0.35166667 | AF9: 0.37666667 | AG9: 0.40166667 | AH9: 0.42666667 | AI9: 0.45166667 | AJ9: 0.47666667 | AK9: 0.50166667 | AL9: 0.50166667 | AM9: 0.50166667 | AN9: 0.50166667 | AO9: 0.50166667 | AP9: 0.50166667 | AQ9: 0.50166667 | AR9: 0.50166667 | AS9: 0.50166667 | AT9: 0.50166667 | AU9: 0.51 | AV9: 0.51833333 | AW9: 0.52666667 | AX9: 0.535 | AY9: 0.54333333 | AZ9: 0.55166667 | BA9: 0.56 | BB9: 0.56833333 | BC9: 0.6 | BD9: 0.63 | BE9: 0.66 | BF9: 0.69 | BG9: 0.72 | BH9: 0.75 | BI9: 0.78 | BJ9: 0.81 | BK9: 0.84 | BL9: 0.87 | BM9: 0.9 | BN9: 0.93 | BO9: 0.96 | BP9: 0.99 | BQ9: 1 | BR9: 1 | BS9: 1 | BT9: 1 | BU9: 1 | BV9: 1 | BW9: 1 | BX9: 1 | BY9: 1 | BZ9: 1 | CA9: 1 | CB9: 1 | CC9: 1 | CD9: 1 | CE9: 1 | CF9: 1 | CG9: 1 | CH9: 1 | CI9: 1 | CJ9: 1 | CK9: 1 | CL9: 1 | CM9: 1 | CN9: 1 | CO9: 1 | CP9: 1 | CQ9: 1 | CR9: 1 | CS9: 1 | CT9: 1 | CU9: 1 | CV9: 1 | CW9: 1 | CX9: 1 | CY9: 1 | CZ9: 1 | DA9: 1 | DB9: 1 | DC9: 1 | DD9: 1 | DE9: 1 | DG9: 0.05 | DH9: 0.08 | DI9: 0.1 | DJ9: 0.12666667 | DK9: 0.15166667 | DL9: 0.17666667 | DM9: 0.20166667 | DN9: 0.22666667 | DO9: 0.25166667 | DP9: 0.27666667 | DQ9: 0.30166667 | DR9: 0.32666667 | DS9: 0.35166667 | DT9: 0.37666667 | DU9: 0.40166667 | DV9: 0.42666667 | DW9: 0.45166667 | DX9: 0.47666667 | DY9: 0.50166667 | DZ9: 0.50166667 | EA9: 0.50166667 | EB9: 0.50166667 | EC9: 0.50166667 | ED9: 0.50166667 | EE9: 0.50166667 | EF9: 0.50166667 | EG9: 0.50166667 | EH9: 0.50166667 | EI9: 0.51 | EJ9: 0.51833333 | EK9: 0.52666667 | EL9: 0.535 | EM9: 0.54333333 | EN9: 0.55166667 | EO9: 0.56 | EP9: 0.56833333 | EQ9: 0.6 | ER9: 0.63 | ES9: 0.66 | ET9: 0.69 | EU9: 0.72 | EV9: 0.75 | EW9: 0.78 | EX9: 0.81 | EY9: 0.84 | EZ9: 0.87 | FA9: 0.9 | FB9: 0.93 | FC9: 0.96 | FD9: 0.99 | FE9: 1 | FF9: 1 | FG9: 1 | FH9: 1 | FI9: 1 | FJ9: 1 | FK9: 1 | FL9: 1 | FM9: 1 | FN9: 1 | FO9: 1 | FP9: 1 | FQ9: 1 | FR9: 1 | FS9: 1 | FT9: 1 | FU9: 1 | FV9: 1 | FW9: 1 | FX9: 1 | FY9: 1 | FZ9: 1 | GA9: 1 | GB9: 1 | GC9: 1 | GD9: 1 | GE9: 1 | GF9: 1 | GG9: 1 | GH9: 1 | GI9: 1 | GJ9: 1 | GK9: 1 | GL9: 1 | GM9: 1 | GN9: 1 | GO9: 1 | GP9: 1 | GQ9: 1 | GR9: 1 | GS9: 1 | GU9: =IF(AND(OR(S9="",S9=0),OR(DG9="",DG9=0)),"", MIN(1.2, IFERROR(DG9/IF(OR(S9="",S9=0),1,S9),0))) -> 1 | GV9: =IF(AND(OR(T9="",T9=0),OR(DH9="",DH9=0)),"", MIN(1.2, IFERROR(DH9/IF(OR(T9="",T9=0),1,T9),0))) -> 1 | GW9: =IF(AND(OR(U9="",U9=0),OR(DI9="",DI9=0)),"", MIN(1.2, IFERROR(DI9/IF(OR(U9="",U9=0),1,U9),0))) -> 1 | GX9: =IF(AND(OR(V9="",V9=0),OR(DJ9="",DJ9=0)),"", MIN(1.2, IFERROR(DJ9/IF(OR(V9="",V9=0),1,V9),0))) -> 1 | GY9: =IF(AND(OR(W9="",W9=0),OR(DK9="",DK9=0)),"", MIN(1.2, IFERROR(DK9/IF(OR(W9="",W9=0),1,W9),0))) -> 1 | GZ9: =IF(AND(OR(X9="",X9=0),OR(DL9="",DL9=0)),"", MIN(1.2, IFERROR(DL9/IF(OR(X9="",X9=0),1,X9),0))) -> 1 | HA9: =IF(AND(OR(Y9="",Y9=0),OR(DM9="",DM9=0)),"", MIN(1.2, IFERROR(DM9/IF(OR(Y9="",Y9=0),1,Y9),0))) -> 1 | HB9: =IF(AND(OR(Z9="",Z9=0),OR(DN9="",DN9=0)),"", MIN(1.2, IFERROR(DN9/IF(OR(Z9="",Z9=0),1,Z9),0))) -> 1 | ... KG9: =IF(AND(OR(DE9="",DE9=0),OR(GS9="",GS9=0)),"", MIN(1.2, IFERROR(GS9/IF(OR(DE9="",DE9=0),1,DE9),0))) -> 1
B10: 3 | C10: MAN | D10: PIC LV belum konsisten menindaklanjuti temuan karena tidak ada daily control board dan forum eskalasi. | E10: Quick Action | F10: Buat daily control board: status unit, temuan P2H, aging repair, kebutuhan part, dan PIC follow-up. | G10: GS-PIC LV | H10: 46181 | I10: 46188 | J10: =(I10-H10)+1 -> 8 | M10: =IF(AND(K10=0,L10=0),"No Progress",IF(Tbl_SM[[#This Row],[ACTUAL START]]="",0,IF(L10-K10<0,"On Progress",L10-K10))) -> No Progress | N10: =IF(Tbl_SM[[#This Row],[PLAN START]]="","", IF(Tbl_SM[[#This Row],[ACTUAL FINISH]]<>"","CLOSE", IF(Tbl_SM[[#This Row],[ACTUAL START]]<>"","ON PROGRESS", "OPEN"))) -> OPEN | O10: =IF(Tbl_SM[[#This Row],[PLAN START]]="","", IF(Tbl_SM[[#This Row],[ACTUAL FINISH]]<>"","CLOSE", IF(TODAY()>Tbl_SM[[#This Row],[DUE DATA]],"OVERDUE", IF((Tbl_SM[[#This Row],[DUE DATA]]-TODAY())<=3,"< 3 HARI", IF((Tbl_SM[[#This Row],[DUE DATA]]-TODAY())<=7,"< 7 HARI", IF((Tbl_SM[[#This Row],[DUE DATA]]-TODAY())<=14,"< 14 HARI", "> 14 HARI")))))) -> < 7 HARI | P10: =IF(SUM(S10:AW10)=0,"",IFERROR(MAX(DG10:EK10),"")) -> 0.52666667 | Q10: =IF(Tbl_SM[[#This Row],[STATUS]]="CLOSE",1,0) -> 0 | S10: 0.05 | T10: 0.08 | U10: 0.1 | V10: 0.12666667 | W10: 0.15166667 | X10: 0.17666667 | Y10: 0.20166667 | Z10: 0.22666667 | AA10: 0.25166667 | AB10: 0.27666667 | AC10: 0.30166667 | AD10: 0.32666667 | AE10: 0.35166667 | AF10: 0.37666667 | AG10: 0.40166667 | AH10: 0.42666667 | AI10: 0.45166667 | AJ10: 0.47666667 | AK10: 0.50166667 | AL10: 0.50166667 | AM10: 0.50166667 | AN10: 0.50166667 | AO10: 0.50166667 | AP10: 0.50166667 | AQ10: 0.50166667 | AR10: 0.50166667 | AS10: 0.50166667 | AT10: 0.50166667 | AU10: 0.51 | AV10: 0.51833333 | AW10: 0.52666667 | AX10: 0.535 | AY10: 0.54333333 | AZ10: 0.55166667 | BA10: 0.56 | BB10: 0.56833333 | BC10: 0.6 | BD10: 0.63 | BE10: 0.66 | BF10: 0.69 | BG10: 0.72 | BH10: 0.75 | BI10: 0.78 | BJ10: 0.81 | BK10: 0.84 | BL10: 0.87 | BM10: 0.9 | BN10: 0.93 | BO10: 0.96 | BP10: 0.99 | BQ10: 1 | BR10: 1 | BS10: 1 | BT10: 1 | BU10: 1 | BV10: 1 | BW10: 1 | BX10: 1 | BY10: 1 | BZ10: 1 | CA10: 1 | CB10: 1 | CC10: 1 | CD10: 1 | CE10: 1 | CF10: 1 | CG10: 1 | CH10: 1 | CI10: 1 | CJ10: 1 | CK10: 1 | CL10: 1 | CM10: 1 | CN10: 1 | CO10: 1 | CP10: 1 | CQ10: 1 | CR10: 1 | CS10: 1 | CT10: 1 | CU10: 1 | CV10: 1 | CW10: 1 | CX10: 1 | CY10: 1 | CZ10: 1 | DA10: 1 | DB10: 1 | DC10: 1 | DD10: 1 | DE10: 1 | DG10: 0.05 | DH10: 0.08 | DI10: 0.1 | DJ10: 0.12666667 | DK10: 0.15166667 | DL10: 0.17666667 | DM10: 0.20166667 | DN10: 0.22666667 | DO10: 0.25166667 | DP10: 0.27666667 | DQ10: 0.30166667 | DR10: 0.32666667 | DS10: 0.35166667 | DT10: 0.37666667 | DU10: 0.40166667 | DV10: 0.42666667 | DW10: 0.45166667 | DX10: 0.47666667 | DY10: 0.50166667 | DZ10: 0.50166667 | EA10: 0.50166667 | EB10: 0.50166667 | EC10: 0.50166667 | ED10: 0.50166667 | EE10: 0.50166667 | EF10: 0.50166667 | EG10: 0.50166667 | EH10: 0.50166667 | EI10: 0.51 | EJ10: 0.51833333 | EK10: 0.52666667 | EL10: 0.535 | EM10: 0.54333333 | EN10: 0.55166667 | EO10: 0.56 | EP10: 0.56833333 | EQ10: 0.6 | ER10: 0.63 | ES10: 0.66 | ET10: 0.69 | EU10: 0.72 | EV10: 0.75 | EW10: 0.78 | EX10: 0.81 | EY10: 0.84 | EZ10: 0.87 | FA10: 0.9 | FB10: 0.93 | FC10: 0.96 | FD10: 0.99 | FE10: 1 | FF10: 1 | FG10: 1 | FH10: 1 | FI10: 1 | FJ10: 1 | FK10: 1 | FL10: 1 | FM10: 1 | FN10: 1 | FO10: 1 | FP10: 1 | FQ10: 1 | FR10: 1 | FS10: 1 | FT10: 1 | FU10: 1 | FV10: 1 | FW10: 1 | FX10: 1 | FY10: 1 | FZ10: 1 | GA10: 1 | GB10: 1 | GC10: 1 | GD10: 1 | GE10: 1 | GF10: 1 | GG10: 1 | GH10: 1 | GI10: 1 | GJ10: 1 | GK10: 1 | GL10: 1 | GM10: 1 | GN10: 1 | GO10: 1 | GP10: 1 | GQ10: 1 | GR10: 1 | GS10: 1 | GU10: =IF(AND(OR(S10="",S10=0),OR(DG10="",DG10=0)),"", MIN(1.2, IFERROR(DG10/IF(OR(S10="",S10=0),1,S10),0))) -> 1 | GV10: =IF(AND(OR(T10="",T10=0),OR(DH10="",DH10=0)),"", MIN(1.2, IFERROR(DH10/IF(OR(T10="",T10=0),1,T10),0))) -> 1 | GW10: =IF(AND(OR(U10="",U10=0),OR(DI10="",DI10=0)),"", MIN(1.2, IFERROR(DI10/IF(OR(U10="",U10=0),1,U10),0))) -> 1 | GX10: =IF(AND(OR(V10="",V10=0),OR(DJ10="",DJ10=0)),"", MIN(1.2, IFERROR(DJ10/IF(OR(V10="",V10=0),1,V10),0))) -> 1 | GY10: =IF(AND(OR(W10="",W10=0),OR(DK10="",DK10=0)),"", MIN(1.2, IFERROR(DK10/IF(OR(W10="",W10=0),1,W10),0))) -> 1 | GZ10: =IF(AND(OR(X10="",X10=0),OR(DL10="",DL10=0)),"", MIN(1.2, IFERROR(DL10/IF(OR(X10="",X10=0),1,X10),0))) -> 1 | HA10: =IF(AND(OR(Y10="",Y10=0),OR(DM10="",DM10=0)),"", MIN(1.2, IFERROR(DM10/IF(OR(Y10="",Y10=0),1,Y10),0))) -> 1 | HB10: =IF(AND(OR(Z10="",Z10=0),OR(DN10="",DN10=0)),"", MIN(1.2, IFERROR(DN10/IF(OR(Z10="",Z10=0),1,Z10),0))) -> 1 | ... KG10: =IF(AND(OR(DE10="",DE10=0),OR(GS10="",GS10=0)),"", MIN(1.2, IFERROR(GS10/IF(OR(DE10="",DE10=0),1,DE10),0))) -> 1
B11: 4 | C11: MAN | D11: Kualitas troubleshooting mekanik bervariasi dan repeat job belum menjadi bahan evaluasi. | E11: Quick Action | F11: Review mingguan mekanik berdasarkan diagnosis time, repair time, repeat job, dan kualitas closing WO. | G11: PLANT-GS | H11: 46183 | I11: 46206 | J11: =(I11-H11)+1 -> 24 | M11: =IF(AND(K11=0,L11=0),"No Progress",IF(Tbl_SM[[#This Row],[ACTUAL START]]="",0,IF(L11-K11<0,"On Progress",L11-K11))) -> No Progress | N11: =IF(Tbl_SM[[#This Row],[PLAN START]]="","", IF(Tbl_SM[[#This Row],[ACTUAL FINISH]]<>"","CLOSE", IF(Tbl_SM[[#This Row],[ACTUAL START]]<>"","ON PROGRESS", "OPEN"))) -> OPEN | O11: =IF(Tbl_SM[[#This Row],[PLAN START]]="","", IF(Tbl_SM[[#This Row],[ACTUAL FINISH]]<>"","CLOSE", IF(TODAY()>Tbl_SM[[#This Row],[DUE DATA]],"OVERDUE", IF((Tbl_SM[[#This Row],[DUE DATA]]-TODAY())<=3,"< 3 HARI", IF((Tbl_SM[[#This Row],[DUE DATA]]-TODAY())<=7,"< 7 HARI", IF((Tbl_SM[[#This Row],[DUE DATA]]-TODAY())<=14,"< 14 HARI", "> 14 HARI")))))) -> > 14 HARI | P11: =IF(SUM(S11:AW11)=0,"",IFERROR(MAX(DG11:EK11),"")) -> 0.52666667 | Q11: =IF(Tbl_SM[[#This Row],[STATUS]]="CLOSE",1,0) -> 0 | S11: 0.05 | T11: 0.08 | U11: 0.1 | V11: 0.12666667 | W11: 0.15166667 | X11: 0.17666667 | Y11: 0.20166667 | Z11: 0.22666667 | AA11: 0.25166667 | AB11: 0.27666667 | AC11: 0.30166667 | AD11: 0.32666667 | AE11: 0.35166667 | AF11: 0.37666667 | AG11: 0.40166667 | AH11: 0.42666667 | AI11: 0.45166667 | AJ11: 0.47666667 | AK11: 0.50166667 | AL11: 0.50166667 | AM11: 0.50166667 | AN11: 0.50166667 | AO11: 0.50166667 | AP11: 0.50166667 | AQ11: 0.50166667 | AR11: 0.50166667 | AS11: 0.50166667 | AT11: 0.50166667 | AU11: 0.51 | AV11: 0.51833333 | AW11: 0.52666667 | AX11: 0.535 | AY11: 0.54333333 | AZ11: 0.55166667 | BA11: 0.56 | BB11: 0.56833333 | BC11: 0.6 | BD11: 0.63 | BE11: 0.66 | BF11: 0.69 | BG11: 0.72 | BH11: 0.75 | BI11: 0.78 | BJ11: 0.81 | BK11: 0.84 | BL11: 0.87 | BM11: 0.9 | BN11: 0.93 | BO11: 0.96 | BP11: 0.99 | BQ11: 1 | BR11: 1 | BS11: 1 | BT11: 1 | BU11: 1 | BV11: 1 | BW11: 1 | BX11: 1 | BY11: 1 | BZ11: 1 | CA11: 1 | CB11: 1 | CC11: 1 | CD11: 1 | CE11: 1 | CF11: 1 | CG11: 1 | CH11: 1 | CI11: 1 | CJ11: 1 | CK11: 1 | CL11: 1 | CM11: 1 | CN11: 1 | CO11: 1 | CP11: 1 | CQ11: 1 | CR11: 1 | CS11: 1 | CT11: 1 | CU11: 1 | CV11: 1 | CW11: 1 | CX11: 1 | CY11: 1 | CZ11: 1 | DA11: 1 | DB11: 1 | DC11: 1 | DD11: 1 | DE11: 1 | DG11: 0.05 | DH11: 0.08 | DI11: 0.1 | DJ11: 0.12666667 | DK11: 0.15166667 | DL11: 0.17666667 | DM11: 0.20166667 | DN11: 0.22666667 | DO11: 0.25166667 | DP11: 0.27666667 | DQ11: 0.30166667 | DR11: 0.32666667 | DS11: 0.35166667 | DT11: 0.37666667 | DU11: 0.40166667 | DV11: 0.42666667 | DW11: 0.45166667 | DX11: 0.47666667 | DY11: 0.50166667 | DZ11: 0.50166667 | EA11: 0.50166667 | EB11: 0.50166667 | EC11: 0.50166667 | ED11: 0.50166667 | EE11: 0.50166667 | EF11: 0.50166667 | EG11: 0.50166667 | EH11: 0.50166667 | EI11: 0.51 | EJ11: 0.51833333 | EK11: 0.52666667 | EL11: 0.535 | EM11: 0.54333333 | EN11: 0.55166667 | EO11: 0.56 | EP11: 0.56833333 | EQ11: 0.6 | ER11: 0.63 | ES11: 0.66 | ET11: 0.69 | EU11: 0.72 | EV11: 0.75 | EW11: 0.78 | EX11: 0.81 | EY11: 0.84 | EZ11: 0.87 | FA11: 0.9 | FB11: 0.93 | FC11: 0.96 | FD11: 0.99 | FE11: 1 | FF11: 1 | FG11: 1 | FH11: 1 | FI11: 1 | FJ11: 1 | FK11: 1 | FL11: 1 | FM11: 1 | FN11: 1 | FO11: 1 | FP11: 1 | FQ11: 1 | FR11: 1 | FS11: 1 | FT11: 1 | FU11: 1 | FV11: 1 | FW11: 1 | FX11: 1 | FY11: 1 | FZ11: 1 | GA11: 1 | GB11: 1 | GC11: 1 | GD11: 1 | GE11: 1 | GF11: 1 | GG11: 1 | GH11: 1 | GI11: 1 | GJ11: 1 | GK11: 1 | GL11: 1 | GM11: 1 | GN11: 1 | GO11: 1 | GP11: 1 | GQ11: 1 | GR11: 1 | GS11: 1 | GU11: =IF(AND(OR(S11="",S11=0),OR(DG11="",DG11=0)),"", MIN(1.2, IFERROR(DG11/IF(OR(S11="",S11=0),1,S11),0))) -> 1 | GV11: =IF(AND(OR(T11="",T11=0),OR(DH11="",DH11=0)),"", MIN(1.2, IFERROR(DH11/IF(OR(T11="",T11=0),1,T11),0))) -> 1 | GW11: =IF(AND(OR(U11="",U11=0),OR(DI11="",DI11=0)),"", MIN(1.2, IFERROR(DI11/IF(OR(U11="",U11=0),1,U11),0))) -> 1 | GX11: =IF(AND(OR(V11="",V11=0),OR(DJ11="",DJ11=0)),"", MIN(1.2, IFERROR(DJ11/IF(OR(V11="",V11=0),1,V11),0))) -> 1 | GY11: =IF(AND(OR(W11="",W11=0),OR(DK11="",DK11=0)),"", MIN(1.2, IFERROR(DK11/IF(OR(W11="",W11=0),1,W11),0))) -> 1 | GZ11: =IF(AND(OR(X11="",X11=0),OR(DL11="",DL11=0)),"", MIN(1.2, IFERROR(DL11/IF(OR(X11="",X11=0),1,X11),0))) -> 1 | HA11: =IF(AND(OR(Y11="",Y11=0),OR(DM11="",DM11=0)),"", MIN(1.2, IFERROR(DM11/IF(OR(Y11="",Y11=0),1,Y11),0))) -> 1 | HB11: =IF(AND(OR(Z11="",Z11=0),OR(DN11="",DN11=0)),"", MIN(1.2, IFERROR(DN11/IF(OR(Z11="",Z11=0),1,Z11),0))) -> 1 | ... KG11: =IF(AND(OR(DE11="",DE11=0),OR(GS11="",GS11=0)),"", MIN(1.2, IFERROR(GS11/IF(OR(DE11="",DE11=0),1,DE11),0))) -> 1
B12: 5 | C12: MAN | D12: Kompetensi electrical, engine, brake, dan AC belum merata karena belum ada skill matrix LV. | E12: Long Term / Development | F12: Susun skill matrix; lakukan coaching, pairing mekanik, dan evaluasi kompetensi per sistem. | G12: PLANT-SLD | H12: 46195 | I12: 46248 | J12: =(I12-H12)+1 -> 54 | M12: =IF(AND(K12=0,L12=0),"No Progress",IF(Tbl_SM[[#This Row],[ACTUAL START]]="",0,IF(L12-K12<0,"On Progress",L12-K12))) -> No Progress | N12: =IF(Tbl_SM[[#This Row],[PLAN START]]="","", IF(Tbl_SM[[#This Row],[ACTUAL FINISH]]<>"","CLOSE", IF(Tbl_SM[[#This Row],[ACTUAL START]]<>"","ON PROGRESS", "OPEN"))) -> OPEN | O12: =IF(Tbl_SM[[#This Row],[PLAN START]]="","", IF(Tbl_SM[[#This Row],[ACTUAL FINISH]]<>"","CLOSE", IF(TODAY()>Tbl_SM[[#This Row],[DUE DATA]],"OVERDUE", IF((Tbl_SM[[#This Row],[DUE DATA]]-TODAY())<=3,"< 3 HARI", IF((Tbl_SM[[#This Row],[DUE DATA]]-TODAY())<=7,"< 7 HARI", IF((Tbl_SM[[#This Row],[DUE DATA]]-TODAY())<=14,"< 14 HARI", "> 14 HARI")))))) -> > 14 HARI | P12: =IF(SUM(S12:AW12)=0,"",IFERROR(MAX(DG12:EK12),"")) -> 0.52666667 | Q12: =IF(Tbl_SM[[#This Row],[STATUS]]="CLOSE",1,0) -> 0 | S12: 0.05 | T12: 0.08 | U12: 0.1 | V12: 0.12666667 | W12: 0.15166667 | X12: 0.17666667 | Y12: 0.20166667 | Z12: 0.22666667 | AA12: 0.25166667 | AB12: 0.27666667 | AC12: 0.30166667 | AD12: 0.32666667 | AE12: 0.35166667 | AF12: 0.37666667 | AG12: 0.40166667 | AH12: 0.42666667 | AI12: 0.45166667 | AJ12: 0.47666667 | AK12: 0.50166667 | AL12: 0.50166667 | AM12: 0.50166667 | AN12: 0.50166667 | AO12: 0.50166667 | AP12: 0.50166667 | AQ12: 0.50166667 | AR12: 0.50166667 | AS12: 0.50166667 | AT12: 0.50166667 | AU12: 0.51 | AV12: 0.51833333 | AW12: 0.52666667 | AX12: 0.535 | AY12: 0.54333333 | AZ12: 0.55166667 | BA12: 0.56 | BB12: 0.56833333 | BC12: 0.6 | BD12: 0.63 | BE12: 0.66 | BF12: 0.69 | BG12: 0.72 | BH12: 0.75 | BI12: 0.78 | BJ12: 0.81 | BK12: 0.84 | BL12: 0.87 | BM12: 0.9 | BN12: 0.93 | BO12: 0.96 | BP12: 0.99 | BQ12: 1 | BR12: 1 | BS12: 1 | BT12: 1 | BU12: 1 | BV12: 1 | BW12: 1 | BX12: 1 | BY12: 1 | BZ12: 1 | CA12: 1 | CB12: 1 | CC12: 1 | CD12: 1 | CE12: 1 | CF12: 1 | CG12: 1 | CH12: 1 | CI12: 1 | CJ12: 1 | CK12: 1 | CL12: 1 | CM12: 1 | CN12: 1 | CO12: 1 | CP12: 1 | CQ12: 1 | CR12: 1 | CS12: 1 | CT12: 1 | CU12: 1 | CV12: 1 | CW12: 1 | CX12: 1 | CY12: 1 | CZ12: 1 | DA12: 1 | DB12: 1 | DC12: 1 | DD12: 1 | DE12: 1 | DG12: 0.05 | DH12: 0.08 | DI12: 0.1 | DJ12: 0.12666667 | DK12: 0.15166667 | DL12: 0.17666667 | DM12: 0.20166667 | DN12: 0.22666667 | DO12: 0.25166667 | DP12: 0.27666667 | DQ12: 0.30166667 | DR12: 0.32666667 | DS12: 0.35166667 | DT12: 0.37666667 | DU12: 0.40166667 | DV12: 0.42666667 | DW12: 0.45166667 | DX12: 0.47666667 | DY12: 0.50166667 | DZ12: 0.50166667 | EA12: 0.50166667 | EB12: 0.50166667 | EC12: 0.50166667 | ED12: 0.50166667 | EE12: 0.50166667 | EF12: 0.50166667 | EG12: 0.50166667 | EH12: 0.50166667 | EI12: 0.51 | EJ12: 0.51833333 | EK12: 0.52666667 | EL12: 0.535 | EM12: 0.54333333 | EN12: 0.55166667 | EO12: 0.56 | EP12: 0.56833333 | EQ12: 0.6 | ER12: 0.63 | ES12: 0.66 | ET12: 0.69 | EU12: 0.72 | EV12: 0.75 | EW12: 0.78 | EX12: 0.81 | EY12: 0.84 | EZ12: 0.87 | FA12: 0.9 | FB12: 0.93 | FC12: 0.96 | FD12: 0.99 | FE12: 1 | FF12: 1 | FG12: 1 | FH12: 1 | FI12: 1 | FJ12: 1 | FK12: 1 | FL12: 1 | FM12: 1 | FN12: 1 | FO12: 1 | FP12: 1 | FQ12: 1 | FR12: 1 | FS12: 1 | FT12: 1 | FU12: 1 | FV12: 1 | FW12: 1 | FX12: 1 | FY12: 1 | FZ12: 1 | GA12: 1 | GB12: 1 | GC12: 1 | GD12: 1 | GE12: 1 | GF12: 1 | GG12: 1 | GH12: 1 | GI12: 1 | GJ12: 1 | GK12: 1 | GL12: 1 | GM12: 1 | GN12: 1 | GO12: 1 | GP12: 1 | GQ12: 1 | GR12: 1 | GS12: 1 | GU12: =IF(AND(OR(S12="",S12=0),OR(DG12="",DG12=0)),"", MIN(1.2, IFERROR(DG12/IF(OR(S12="",S12=0),1,S12),0))) -> 1 | GV12: =IF(AND(OR(T12="",T12=0),OR(DH12="",DH12=0)),"", MIN(1.2, IFERROR(DH12/IF(OR(T12="",T12=0),1,T12),0))) -> 1 | GW12: =IF(AND(OR(U12="",U12=0),OR(DI12="",DI12=0)),"", MIN(1.2, IFERROR(DI12/IF(OR(U12="",U12=0),1,U12),0))) -> 1 | GX12: =IF(AND(OR(V12="",V12=0),OR(DJ12="",DJ12=0)),"", MIN(1.2, IFERROR(DJ12/IF(OR(V12="",V12=0),1,V12),0))) -> 1 | GY12: =IF(AND(OR(W12="",W12=0),OR(DK12="",DK12=0)),"", MIN(1.2, IFERROR(DK12/IF(OR(W12="",W12=0),1,W12),0))) -> 1 | GZ12: =IF(AND(OR(X12="",X12=0),OR(DL12="",DL12=0)),"", MIN(1.2, IFERROR(DL12/IF(OR(X12="",X12=0),1,X12),0))) -> 1 | HA12: =IF(AND(OR(Y12="",Y12=0),OR(DM12="",DM12=0)),"", MIN(1.2, IFERROR(DM12/IF(OR(Y12="",Y12=0),1,Y12),0))) -> 1 | HB12: =IF(AND(OR(Z12="",Z12=0),OR(DN12="",DN12=0)),"", MIN(1.2, IFERROR(DN12/IF(OR(Z12="",Z12=0),1,Z12),0))) -> 1 | ... KG12: =IF(AND(OR(DE12="",DE12=0),OR(GS12="",GS12=0)),"", MIN(1.2, IFERROR(GS12/IF(OR(DE12="",DE12=0),1,DE12),0))) -> 1
B13: 6 | C13: METHOD | D13: P2H menjadi formalitas karena checklist terlalu umum dan tidak memberi panduan gejala abnormal. | E13: Quick Action | F13: Revisi checklist P2H dengan foto standar, item kritikal, klasifikasi temuan, dan bukti pemeriksaan. | G13: GS-PLANT-SHE | H13: 46181 | I13: 46199 | J13: =(I13-H13)+1 -> 19 | M13: =IF(AND(K13=0,L13=0),"No Progress",IF(Tbl_SM[[#This Row],[ACTUAL START]]="",0,IF(L13-K13<0,"On Progress",L13-K13))) -> No Progress | N13: =IF(Tbl_SM[[#This Row],[PLAN START]]="","", IF(Tbl_SM[[#This Row],[ACTUAL FINISH]]<>"","CLOSE", IF(Tbl_SM[[#This Row],[ACTUAL START]]<>"","ON PROGRESS", "OPEN"))) -> OPEN | O13: =IF(Tbl_SM[[#This Row],[PLAN START]]="","", IF(Tbl_SM[[#This Row],[ACTUAL FINISH]]<>"","CLOSE", IF(TODAY()>Tbl_SM[[#This Row],[DUE DATA]],"OVERDUE", IF((Tbl_SM[[#This Row],[DUE DATA]]-TODAY())<=3,"< 3 HARI", IF((Tbl_SM[[#This Row],[DUE DATA]]-TODAY())<=7,"< 7 HARI", IF((Tbl_SM[[#This Row],[DUE DATA]]-TODAY())<=14,"< 14 HARI", "> 14 HARI")))))) -> > 14 HARI | P13: =IF(SUM(S13:AW13)=0,"",IFERROR(MAX(DG13:EK13),"")) -> 0.52666667 | Q13: =IF(Tbl_SM[[#This Row],[STATUS]]="CLOSE",1,0) -> 0 | S13: 0.05 | T13: 0.08 | U13: 0.1 | V13: 0.12666667 | W13: 0.15166667 | X13: 0.17666667 | Y13: 0.20166667 | Z13: 0.22666667 | AA13: 0.25166667 | AB13: 0.27666667 | AC13: 0.30166667 | AD13: 0.32666667 | AE13: 0.35166667 | AF13: 0.37666667 | AG13: 0.40166667 | AH13: 0.42666667 | AI13: 0.45166667 | AJ13: 0.47666667 | AK13: 0.50166667 | AL13: 0.50166667 | AM13: 0.50166667 | AN13: 0.50166667 | AO13: 0.50166667 | AP13: 0.50166667 | AQ13: 0.50166667 | AR13: 0.50166667 | AS13: 0.50166667 | AT13: 0.50166667 | AU13: 0.51 | AV13: 0.51833333 | AW13: 0.52666667 | AX13: 0.535 | AY13: 0.54333333 | AZ13: 0.55166667 | BA13: 0.56 | BB13: 0.56833333 | BC13: 0.6 | BD13: 0.63 | BE13: 0.66 | BF13: 0.69 | BG13: 0.72 | BH13: 0.75 | BI13: 0.78 | BJ13: 0.81 | BK13: 0.84 | BL13: 0.87 | BM13: 0.9 | BN13: 0.93 | BO13: 0.96 | BP13: 0.99 | BQ13: 1 | BR13: 1 | BS13: 1 | BT13: 1 | BU13: 1 | BV13: 1 | BW13: 1 | BX13: 1 | BY13: 1 | BZ13: 1 | CA13: 1 | CB13: 1 | CC13: 1 | CD13: 1 | CE13: 1 | CF13: 1 | CG13: 1 | CH13: 1 | CI13: 1 | CJ13: 1 | CK13: 1 | CL13: 1 | CM13: 1 | CN13: 1 | CO13: 1 | CP13: 1 | CQ13: 1 | CR13: 1 | CS13: 1 | CT13: 1 | CU13: 1 | CV13: 1 | CW13: 1 | CX13: 1 | CY13: 1 | CZ13: 1 | DA13: 1 | DB13: 1 | DC13: 1 | DD13: 1 | DE13: 1 | DG13: 0.05 | DH13: 0.08 | DI13: 0.1 | DJ13: 0.12666667 | DK13: 0.15166667 | DL13: 0.17666667 | DM13: 0.20166667 | DN13: 0.22666667 | DO13: 0.25166667 | DP13: 0.27666667 | DQ13: 0.30166667 | DR13: 0.32666667 | DS13: 0.35166667 | DT13: 0.37666667 | DU13: 0.40166667 | DV13: 0.42666667 | DW13: 0.45166667 | DX13: 0.47666667 | DY13: 0.50166667 | DZ13: 0.50166667 | EA13: 0.50166667 | EB13: 0.50166667 | EC13: 0.50166667 | ED13: 0.50166667 | EE13: 0.50166667 | EF13: 0.50166667 | EG13: 0.50166667 | EH13: 0.50166667 | EI13: 0.51 | EJ13: 0.51833333 | EK13: 0.52666667 | EL13: 0.535 | EM13: 0.54333333 | EN13: 0.55166667 | EO13: 0.56 | EP13: 0.56833333 | EQ13: 0.6 | ER13: 0.63 | ES13: 0.66 | ET13: 0.69 | EU13: 0.72 | EV13: 0.75 | EW13: 0.78 | EX13: 0.81 | EY13: 0.84 | EZ13: 0.87 | FA13: 0.9 | FB13: 0.93 | FC13: 0.96 | FD13: 0.99 | FE13: 1 | FF13: 1 | FG13: 1 | FH13: 1 | FI13: 1 | FJ13: 1 | FK13: 1 | FL13: 1 | FM13: 1 | FN13: 1 | FO13: 1 | FP13: 1 | FQ13: 1 | FR13: 1 | FS13: 1 | FT13: 1 | FU13: 1 | FV13: 1 | FW13: 1 | FX13: 1 | FY13: 1 | FZ13: 1 | GA13: 1 | GB13: 1 | GC13: 1 | GD13: 1 | GE13: 1 | GF13: 1 | GG13: 1 | GH13: 1 | GI13: 1 | GJ13: 1 | GK13: 1 | GL13: 1 | GM13: 1 | GN13: 1 | GO13: 1 | GP13: 1 | GQ13: 1 | GR13: 1 | GS13: 1 | GU13: =IF(AND(OR(S13="",S13=0),OR(DG13="",DG13=0)),"", MIN(1.2, IFERROR(DG13/IF(OR(S13="",S13=0),1,S13),0))) -> 1 | GV13: =IF(AND(OR(T13="",T13=0),OR(DH13="",DH13=0)),"", MIN(1.2, IFERROR(DH13/IF(OR(T13="",T13=0),1,T13),0))) -> 1 | GW13: =IF(AND(OR(U13="",U13=0),OR(DI13="",DI13=0)),"", MIN(1.2, IFERROR(DI13/IF(OR(U13="",U13=0),1,U13),0))) -> 1 | GX13: =IF(AND(OR(V13="",V13=0),OR(DJ13="",DJ13=0)),"", MIN(1.2, IFERROR(DJ13/IF(OR(V13="",V13=0),1,V13),0))) -> 1 | GY13: =IF(AND(OR(W13="",W13=0),OR(DK13="",DK13=0)),"", MIN(1.2, IFERROR(DK13/IF(OR(W13="",W13=0),1,W13),0))) -> 1 | GZ13: =IF(AND(OR(X13="",X13=0),OR(DL13="",DL13=0)),"", MIN(1.2, IFERROR(DL13/IF(OR(X13="",X13=0),1,X13),0))) -> 1 | HA13: =IF(AND(OR(Y13="",Y13=0),OR(DM13="",DM13=0)),"", MIN(1.2, IFERROR(DM13/IF(OR(Y13="",Y13=0),1,Y13),0))) -> 1 | HB13: =IF(AND(OR(Z13="",Z13=0),OR(DN13="",DN13=0)),"", MIN(1.2, IFERROR(DN13/IF(OR(Z13="",Z13=0),1,Z13),0))) -> 1 | ... KG13: =IF(AND(OR(DE13="",DE13=0),OR(GS13="",GS13=0)),"", MIN(1.2, IFERROR(GS13/IF(OR(DE13="",DE13=0),1,DE13),0))) -> 1
B14: 7 | C14: METHOD | D14: Temuan P2H tidak tertutup karena tidak ada SLA, prioritas risiko, dan verifikasi closing. | E14: Quick Action | F14: Buat register temuan P2H dengan klasifikasi A/B/C, SLA, PIC, evidence, dan verifikasi closing. | G14: GS-PLANT | H14: 46188 | I14: 46206 | J14: =(I14-H14)+1 -> 19 | M14: =IF(AND(K14=0,L14=0),"No Progress",IF(Tbl_SM[[#This Row],[ACTUAL START]]="",0,IF(L14-K14<0,"On Progress",L14-K14))) -> No Progress | N14: =IF(Tbl_SM[[#This Row],[PLAN START]]="","", IF(Tbl_SM[[#This Row],[ACTUAL FINISH]]<>"","CLOSE", IF(Tbl_SM[[#This Row],[ACTUAL START]]<>"","ON PROGRESS", "OPEN"))) -> OPEN | O14: =IF(Tbl_SM[[#This Row],[PLAN START]]="","", IF(Tbl_SM[[#This Row],[ACTUAL FINISH]]<>"","CLOSE", IF(TODAY()>Tbl_SM[[#This Row],[DUE DATA]],"OVERDUE", IF((Tbl_SM[[#This Row],[DUE DATA]]-TODAY())<=3,"< 3 HARI", IF((Tbl_SM[[#This Row],[DUE DATA]]-TODAY())<=7,"< 7 HARI", IF((Tbl_SM[[#This Row],[DUE DATA]]-TODAY())<=14,"< 14 HARI", "> 14 HARI")))))) -> > 14 HARI | P14: =IF(SUM(S14:AW14)=0,"",IFERROR(MAX(DG14:EK14),"")) -> 0.52666667 | Q14: =IF(Tbl_SM[[#This Row],[STATUS]]="CLOSE",1,0) -> 0 | S14: 0.05 | T14: 0.08 | U14: 0.1 | V14: 0.12666667 | W14: 0.15166667 | X14: 0.17666667 | Y14: 0.20166667 | Z14: 0.22666667 | AA14: 0.25166667 | AB14: 0.27666667 | AC14: 0.30166667 | AD14: 0.32666667 | AE14: 0.35166667 | AF14: 0.37666667 | AG14: 0.40166667 | AH14: 0.42666667 | AI14: 0.45166667 | AJ14: 0.47666667 | AK14: 0.50166667 | AL14: 0.50166667 | AM14: 0.50166667 | AN14: 0.50166667 | AO14: 0.50166667 | AP14: 0.50166667 | AQ14: 0.50166667 | AR14: 0.50166667 | AS14: 0.50166667 | AT14: 0.50166667 | AU14: 0.51 | AV14: 0.51833333 | AW14: 0.52666667 | AX14: 0.535 | AY14: 0.54333333 | AZ14: 0.55166667 | BA14: 0.56 | BB14: 0.56833333 | BC14: 0.6 | BD14: 0.63 | BE14: 0.66 | BF14: 0.69 | BG14: 0.72 | BH14: 0.75 | BI14: 0.78 | BJ14: 0.81 | BK14: 0.84 | BL14: 0.87 | BM14: 0.9 | BN14: 0.93 | BO14: 0.96 | BP14: 0.99 | BQ14: 1 | BR14: 1 | BS14: 1 | BT14: 1 | BU14: 1 | BV14: 1 | BW14: 1 | BX14: 1 | BY14: 1 | BZ14: 1 | CA14: 1 | CB14: 1 | CC14: 1 | CD14: 1 | CE14: 1 | CF14: 1 | CG14: 1 | CH14: 1 | CI14: 1 | CJ14: 1 | CK14: 1 | CL14: 1 | CM14: 1 | CN14: 1 | CO14: 1 | CP14: 1 | CQ14: 1 | CR14: 1 | CS14: 1 | CT14: 1 | CU14: 1 | CV14: 1 | CW14: 1 | CX14: 1 | CY14: 1 | CZ14: 1 | DA14: 1 | DB14: 1 | DC14: 1 | DD14: 1 | DE14: 1 | DG14: 0.05 | DH14: 0.08 | DI14: 0.1 | DJ14: 0.12666667 | DK14: 0.15166667 | DL14: 0.17666667 | DM14: 0.20166667 | DN14: 0.22666667 | DO14: 0.25166667 | DP14: 0.27666667 | DQ14: 0.30166667 | DR14: 0.32666667 | DS14: 0.35166667 | DT14: 0.37666667 | DU14: 0.40166667 | DV14: 0.42666667 | DW14: 0.45166667 | DX14: 0.47666667 | DY14: 0.50166667 | DZ14: 0.50166667 | EA14: 0.50166667 | EB14: 0.50166667 | EC14: 0.50166667 | ED14: 0.50166667 | EE14: 0.50166667 | EF14: 0.50166667 | EG14: 0.50166667 | EH14: 0.50166667 | EI14: 0.51 | EJ14: 0.51833333 | EK14: 0.52666667 | EL14: 0.535 | EM14: 0.54333333 | EN14: 0.55166667 | EO14: 0.56 | EP14: 0.56833333 | EQ14: 0.6 | ER14: 0.63 | ES14: 0.66 | ET14: 0.69 | EU14: 0.72 | EV14: 0.75 | EW14: 0.78 | EX14: 0.81 | EY14: 0.84 | EZ14: 0.87 | FA14: 0.9 | FB14: 0.93 | FC14: 0.96 | FD14: 0.99 | FE14: 1 | FF14: 1 | FG14: 1 | FH14: 1 | FI14: 1 | FJ14: 1 | FK14: 1 | FL14: 1 | FM14: 1 | FN14: 1 | FO14: 1 | FP14: 1 | FQ14: 1 | FR14: 1 | FS14: 1 | FT14: 1 | FU14: 1 | FV14: 1 | FW14: 1 | FX14: 1 | FY14: 1 | FZ14: 1 | GA14: 1 | GB14: 1 | GC14: 1 | GD14: 1 | GE14: 1 | GF14: 1 | GG14: 1 | GH14: 1 | GI14: 1 | GJ14: 1 | GK14: 1 | GL14: 1 | GM14: 1 | GN14: 1 | GO14: 1 | GP14: 1 | GQ14: 1 | GR14: 1 | GS14: 1 | GU14: =IF(AND(OR(S14="",S14=0),OR(DG14="",DG14=0)),"", MIN(1.2, IFERROR(DG14/IF(OR(S14="",S14=0),1,S14),0))) -> 1 | GV14: =IF(AND(OR(T14="",T14=0),OR(DH14="",DH14=0)),"", MIN(1.2, IFERROR(DH14/IF(OR(T14="",T14=0),1,T14),0))) -> 1 | GW14: =IF(AND(OR(U14="",U14=0),OR(DI14="",DI14=0)),"", MIN(1.2, IFERROR(DI14/IF(OR(U14="",U14=0),1,U14),0))) -> 1 | GX14: =IF(AND(OR(V14="",V14=0),OR(DJ14="",DJ14=0)),"", MIN(1.2, IFERROR(DJ14/IF(OR(V14="",V14=0),1,V14),0))) -> 1 | GY14: =IF(AND(OR(W14="",W14=0),OR(DK14="",DK14=0)),"", MIN(1.2, IFERROR(DK14/IF(OR(W14="",W14=0),1,W14),0))) -> 1 | GZ14: =IF(AND(OR(X14="",X14=0),OR(DL14="",DL14=0)),"", MIN(1.2, IFERROR(DL14/IF(OR(X14="",X14=0),1,X14),0))) -> 1 | HA14: =IF(AND(OR(Y14="",Y14=0),OR(DM14="",DM14=0)),"", MIN(1.2, IFERROR(DM14/IF(OR(Y14="",Y14=0),1,Y14),0))) -> 1 | HB14: =IF(AND(OR(Z14="",Z14=0),OR(DN14="",DN14=0)),"", MIN(1.2, IFERROR(DN14/IF(OR(Z14="",Z14=0),1,Z14),0))) -> 1 | ... KG14: =IF(AND(OR(DE14="",DE14=0),OR(GS14="",GS14=0)),"", MIN(1.2, IFERROR(GS14/IF(OR(DE14="",DE14=0),1,DE14),0))) -> 1
B15: 8 | C15: METHOD | D15: PM check tidak efektif karena hanya fokus penggantian periodik, belum berbasis kondisi unit. | E15: Long Term / Development | F15: Tambahkan condition-based inspection saat PM: leak, brake, steering, suspension, electrical, tire, dan abnormal noise. | G15: PLANT | H15: 46195 | I15: 46227 | J15: =(I15-H15)+1 -> 33 | M15: =IF(AND(K15=0,L15=0),"No Progress",IF(Tbl_SM[[#This Row],[ACTUAL START]]="",0,IF(L15-K15<0,"On Progress",L15-K15))) -> No Progress | N15: =IF(Tbl_SM[[#This Row],[PLAN START]]="","", IF(Tbl_SM[[#This Row],[ACTUAL FINISH]]<>"","CLOSE", IF(Tbl_SM[[#This Row],[ACTUAL START]]<>"","ON PROGRESS", "OPEN"))) -> OPEN | O15: =IF(Tbl_SM[[#This Row],[PLAN START]]="","", IF(Tbl_SM[[#This Row],[ACTUAL FINISH]]<>"","CLOSE", IF(TODAY()>Tbl_SM[[#This Row],[DUE DATA]],"OVERDUE", IF((Tbl_SM[[#This Row],[DUE DATA]]-TODAY())<=3,"< 3 HARI", IF((Tbl_SM[[#This Row],[DUE DATA]]-TODAY())<=7,"< 7 HARI", IF((Tbl_SM[[#This Row],[DUE DATA]]-TODAY())<=14,"< 14 HARI", "> 14 HARI")))))) -> > 14 HARI | P15: =IF(SUM(S15:AW15)=0,"",IFERROR(MAX(DG15:EK15),"")) -> 0.52666667 | Q15: =IF(Tbl_SM[[#This Row],[STATUS]]="CLOSE",1,0) -> 0 | S15: 0.05 | T15: 0.08 | U15: 0.1 | V15: 0.12666667 | W15: 0.15166667 | X15: 0.17666667 | Y15: 0.20166667 | Z15: 0.22666667 | AA15: 0.25166667 | AB15: 0.27666667 | AC15: 0.30166667 | AD15: 0.32666667 | AE15: 0.35166667 | AF15: 0.37666667 | AG15: 0.40166667 | AH15: 0.42666667 | AI15: 0.45166667 | AJ15: 0.47666667 | AK15: 0.50166667 | AL15: 0.50166667 | AM15: 0.50166667 | AN15: 0.50166667 | AO15: 0.50166667 | AP15: 0.50166667 | AQ15: 0.50166667 | AR15: 0.50166667 | AS15: 0.50166667 | AT15: 0.50166667 | AU15: 0.51 | AV15: 0.51833333 | AW15: 0.52666667 | AX15: 0.535 | AY15: 0.54333333 | AZ15: 0.55166667 | BA15: 0.56 | BB15: 0.56833333 | BC15: 0.6 | BD15: 0.63 | BE15: 0.66 | BF15: 0.69 | BG15: 0.72 | BH15: 0.75 | BI15: 0.78 | BJ15: 0.81 | BK15: 0.84 | BL15: 0.87 | BM15: 0.9 | BN15: 0.93 | BO15: 0.96 | BP15: 0.99 | BQ15: 1 | BR15: 1 | BS15: 1 | BT15: 1 | BU15: 1 | BV15: 1 | BW15: 1 | BX15: 1 | BY15: 1 | BZ15: 1 | CA15: 1 | CB15: 1 | CC15: 1 | CD15: 1 | CE15: 1 | CF15: 1 | CG15: 1 | CH15: 1 | CI15: 1 | CJ15: 1 | CK15: 1 | CL15: 1 | CM15: 1 | CN15: 1 | CO15: 1 | CP15: 1 | CQ15: 1 | CR15: 1 | CS15: 1 | CT15: 1 | CU15: 1 | CV15: 1 | CW15: 1 | CX15: 1 | CY15: 1 | CZ15: 1 | DA15: 1 | DB15: 1 | DC15: 1 | DD15: 1 | DE15: 1 | DG15: 0.05 | DH15: 0.08 | DI15: 0.1 | DJ15: 0.12666667 | DK15: 0.15166667 | DL15: 0.17666667 | DM15: 0.20166667 | DN15: 0.22666667 | DO15: 0.25166667 | DP15: 0.27666667 | DQ15: 0.30166667 | DR15: 0.32666667 | DS15: 0.35166667 | DT15: 0.37666667 | DU15: 0.40166667 | DV15: 0.42666667 | DW15: 0.45166667 | DX15: 0.47666667 | DY15: 0.50166667 | DZ15: 0.50166667 | EA15: 0.50166667 | EB15: 0.50166667 | EC15: 0.50166667 | ED15: 0.50166667 | EE15: 0.50166667 | EF15: 0.50166667 | EG15: 0.50166667 | EH15: 0.50166667 | EI15: 0.51 | EJ15: 0.51833333 | EK15: 0.52666667 | EL15: 0.535 | EM15: 0.54333333 | EN15: 0.55166667 | EO15: 0.56 | EP15: 0.56833333 | EQ15: 0.6 | ER15: 0.63 | ES15: 0.66 | ET15: 0.69 | EU15: 0.72 | EV15: 0.75 | EW15: 0.78 | EX15: 0.81 | EY15: 0.84 | EZ15: 0.87 | FA15: 0.9 | FB15: 0.93 | FC15: 0.96 | FD15: 0.99 | FE15: 1 | FF15: 1 | FG15: 1 | FH15: 1 | FI15: 1 | FJ15: 1 | FK15: 1 | FL15: 1 | FM15: 1 | FN15: 1 | FO15: 1 | FP15: 1 | FQ15: 1 | FR15: 1 | FS15: 1 | FT15: 1 | FU15: 1 | FV15: 1 | FW15: 1 | FX15: 1 | FY15: 1 | FZ15: 1 | GA15: 1 | GB15: 1 | GC15: 1 | GD15: 1 | GE15: 1 | GF15: 1 | GG15: 1 | GH15: 1 | GI15: 1 | GJ15: 1 | GK15: 1 | GL15: 1 | GM15: 1 | GN15: 1 | GO15: 1 | GP15: 1 | GQ15: 1 | GR15: 1 | GS15: 1 | GU15: =IF(AND(OR(S15="",S15=0),OR(DG15="",DG15=0)),"", MIN(1.2, IFERROR(DG15/IF(OR(S15="",S15=0),1,S15),0))) -> 1 | GV15: =IF(AND(OR(T15="",T15=0),OR(DH15="",DH15=0)),"", MIN(1.2, IFERROR(DH15/IF(OR(T15="",T15=0),1,T15),0))) -> 1 | GW15: =IF(AND(OR(U15="",U15=0),OR(DI15="",DI15=0)),"", MIN(1.2, IFERROR(DI15/IF(OR(U15="",U15=0),1,U15),0))) -> 1 | GX15: =IF(AND(OR(V15="",V15=0),OR(DJ15="",DJ15=0)),"", MIN(1.2, IFERROR(DJ15/IF(OR(V15="",V15=0),1,V15),0))) -> 1 | GY15: =IF(AND(OR(W15="",W15=0),OR(DK15="",DK15=0)),"", MIN(1.2, IFERROR(DK15/IF(OR(W15="",W15=0),1,W15),0))) -> 1 | GZ15: =IF(AND(OR(X15="",X15=0),OR(DL15="",DL15=0)),"", MIN(1.2, IFERROR(DL15/IF(OR(X15="",X15=0),1,X15),0))) -> 1 | HA15: =IF(AND(OR(Y15="",Y15=0),OR(DM15="",DM15=0)),"", MIN(1.2, IFERROR(DM15/IF(OR(Y15="",Y15=0),1,Y15),0))) -> 1 | HB15: =IF(AND(OR(Z15="",Z15=0),OR(DN15="",DN15=0)),"", MIN(1.2, IFERROR(DN15/IF(OR(Z15="",Z15=0),1,Z15),0))) -> 1 | ... KG15: =IF(AND(OR(DE15="",DE15=0),OR(GS15="",GS15=0)),"", MIN(1.2, IFERROR(GS15/IF(OR(DE15="",DE15=0),1,DE15),0))) -> 1
B16: 9 | C16: METHOD | D16: Tidak ada inspeksi menyeluruh sehingga kerusakan laten baru diketahui saat breakdown. | E16: Quick Action | F16: Laksanakan baseline comprehensive inspection seluruh LV dan keluarkan health score serta repair recommendation. | G16: GS-PLANT-SHE | H16: 46183 | I16: 46213 | J16: =(I16-H16)+1 -> 31 | M16: =IF(AND(K16=0,L16=0),"No Progress",IF(Tbl_SM[[#This Row],[ACTUAL START]]="",0,IF(L16-K16<0,"On Progress",L16-K16))) -> No Progress | N16: =IF(Tbl_SM[[#This Row],[PLAN START]]="","", IF(Tbl_SM[[#This Row],[ACTUAL FINISH]]<>"","CLOSE", IF(Tbl_SM[[#This Row],[ACTUAL START]]<>"","ON PROGRESS", "OPEN"))) -> OPEN | O16: =IF(Tbl_SM[[#This Row],[PLAN START]]="","", IF(Tbl_SM[[#This Row],[ACTUAL FINISH]]<>"","CLOSE", IF(TODAY()>Tbl_SM[[#This Row],[DUE DATA]],"OVERDUE", IF((Tbl_SM[[#This Row],[DUE DATA]]-TODAY())<=3,"< 3 HARI", IF((Tbl_SM[[#This Row],[DUE DATA]]-TODAY())<=7,"< 7 HARI", IF((Tbl_SM[[#This Row],[DUE DATA]]-TODAY())<=14,"< 14 HARI", "> 14 HARI")))))) -> > 14 HARI | P16: =IF(SUM(S16:AW16)=0,"",IFERROR(MAX(DG16:EK16),"")) -> 0.52666667 | Q16: =IF(Tbl_SM[[#This Row],[STATUS]]="CLOSE",1,0) -> 0 | S16: 0.05 | T16: 0.08 | U16: 0.1 | V16: 0.12666667 | W16: 0.15166667 | X16: 0.17666667 | Y16: 0.20166667 | Z16: 0.22666667 | AA16: 0.25166667 | AB16: 0.27666667 | AC16: 0.30166667 | AD16: 0.32666667 | AE16: 0.35166667 | AF16: 0.37666667 | AG16: 0.40166667 | AH16: 0.42666667 | AI16: 0.45166667 | AJ16: 0.47666667 | AK16: 0.50166667 | AL16: 0.50166667 | AM16: 0.50166667 | AN16: 0.50166667 | AO16: 0.50166667 | AP16: 0.50166667 | AQ16: 0.50166667 | AR16: 0.50166667 | AS16: 0.50166667 | AT16: 0.50166667 | AU16: 0.51 | AV16: 0.51833333 | AW16: 0.52666667 | AX16: 0.535 | AY16: 0.54333333 | AZ16: 0.55166667 | BA16: 0.56 | BB16: 0.56833333 | BC16: 0.6 | BD16: 0.63 | BE16: 0.66 | BF16: 0.69 | BG16: 0.72 | BH16: 0.75 | BI16: 0.78 | BJ16: 0.81 | BK16: 0.84 | BL16: 0.87 | BM16: 0.9 | BN16: 0.93 | BO16: 0.96 | BP16: 0.99 | BQ16: 1 | BR16: 1 | BS16: 1 | BT16: 1 | BU16: 1 | BV16: 1 | BW16: 1 | BX16: 1 | BY16: 1 | BZ16: 1 | CA16: 1 | CB16: 1 | CC16: 1 | CD16: 1 | CE16: 1 | CF16: 1 | CG16: 1 | CH16: 1 | CI16: 1 | CJ16: 1 | CK16: 1 | CL16: 1 | CM16: 1 | CN16: 1 | CO16: 1 | CP16: 1 | CQ16: 1 | CR16: 1 | CS16: 1 | CT16: 1 | CU16: 1 | CV16: 1 | CW16: 1 | CX16: 1 | CY16: 1 | CZ16: 1 | DA16: 1 | DB16: 1 | DC16: 1 | DD16: 1 | DE16: 1 | DG16: 0.05 | DH16: 0.08 | DI16: 0.1 | DJ16: 0.12666667 | DK16: 0.15166667 | DL16: 0.17666667 | DM16: 0.20166667 | DN16: 0.22666667 | DO16: 0.25166667 | DP16: 0.27666667 | DQ16: 0.30166667 | DR16: 0.32666667 | DS16: 0.35166667 | DT16: 0.37666667 | DU16: 0.40166667 | DV16: 0.42666667 | DW16: 0.45166667 | DX16: 0.47666667 | DY16: 0.50166667 | DZ16: 0.50166667 | EA16: 0.50166667 | EB16: 0.50166667 | EC16: 0.50166667 | ED16: 0.50166667 | EE16: 0.50166667 | EF16: 0.50166667 | EG16: 0.50166667 | EH16: 0.50166667 | EI16: 0.51 | EJ16: 0.51833333 | EK16: 0.52666667 | EL16: 0.535 | EM16: 0.54333333 | EN16: 0.55166667 | EO16: 0.56 | EP16: 0.56833333 | EQ16: 0.6 | ER16: 0.63 | ES16: 0.66 | ET16: 0.69 | EU16: 0.72 | EV16: 0.75 | EW16: 0.78 | EX16: 0.81 | EY16: 0.84 | EZ16: 0.87 | FA16: 0.9 | FB16: 0.93 | FC16: 0.96 | FD16: 0.99 | FE16: 1 | FF16: 1 | FG16: 1 | FH16: 1 | FI16: 1 | FJ16: 1 | FK16: 1 | FL16: 1 | FM16: 1 | FN16: 1 | FO16: 1 | FP16: 1 | FQ16: 1 | FR16: 1 | FS16: 1 | FT16: 1 | FU16: 1 | FV16: 1 | FW16: 1 | FX16: 1 | FY16: 1 | FZ16: 1 | GA16: 1 | GB16: 1 | GC16: 1 | GD16: 1 | GE16: 1 | GF16: 1 | GG16: 1 | GH16: 1 | GI16: 1 | GJ16: 1 | GK16: 1 | GL16: 1 | GM16: 1 | GN16: 1 | GO16: 1 | GP16: 1 | GQ16: 1 | GR16: 1 | GS16: 1 | GU16: =IF(AND(OR(S16="",S16=0),OR(DG16="",DG16=0)),"", MIN(1.2, IFERROR(DG16/IF(OR(S16="",S16=0),1,S16),0))) -> 1 | GV16: =IF(AND(OR(T16="",T16=0),OR(DH16="",DH16=0)),"", MIN(1.2, IFERROR(DH16/IF(OR(T16="",T16=0),1,T16),0))) -> 1 | GW16: =IF(AND(OR(U16="",U16=0),OR(DI16="",DI16=0)),"", MIN(1.2, IFERROR(DI16/IF(OR(U16="",U16=0),1,U16),0))) -> 1 | GX16: =IF(AND(OR(V16="",V16=0),OR(DJ16="",DJ16=0)),"", MIN(1.2, IFERROR(DJ16/IF(OR(V16="",V16=0),1,V16),0))) -> 1 | GY16: =IF(AND(OR(W16="",W16=0),OR(DK16="",DK16=0)),"", MIN(1.2, IFERROR(DK16/IF(OR(W16="",W16=0),1,W16),0))) -> 1 | GZ16: =IF(AND(OR(X16="",X16=0),OR(DL16="",DL16=0)),"", MIN(1.2, IFERROR(DL16/IF(OR(X16="",X16=0),1,X16),0))) -> 1 | HA16: =IF(AND(OR(Y16="",Y16=0),OR(DM16="",DM16=0)),"", MIN(1.2, IFERROR(DM16/IF(OR(Y16="",Y16=0),1,Y16),0))) -> 1 | HB16: =IF(AND(OR(Z16="",Z16=0),OR(DN16="",DN16=0)),"", MIN(1.2, IFERROR(DN16/IF(OR(Z16="",Z16=0),1,Z16),0))) -> 1 | ... KG16: =IF(AND(OR(DE16="",DE16=0),OR(GS16="",GS16=0)),"", MIN(1.2, IFERROR(GS16/IF(OR(DE16="",DE16=0),1,DE16),0))) -> 1
B17: 10 | C17: METHOD | D17: Lead time repair panjang karena tidak ada jalur eskalasi berdasarkan aging. | E17: Long Term / Development | F17: Terapkan SOP eskalasi repair >24 jam, >3 hari, >7 hari dengan kebutuhan keputusan yang jelas. | G17: GS-PLANT-LOG | H17: 46204 | I17: 46234 | J17: =(I17-H17)+1 -> 31 | M17: =IF(AND(K17=0,L17=0),"No Progress",IF(Tbl_SM[[#This Row],[ACTUAL START]]="",0,IF(L17-K17<0,"On Progress",L17-K17))) -> No Progress | N17: =IF(Tbl_SM[[#This Row],[PLAN START]]="","", IF(Tbl_SM[[#This Row],[ACTUAL FINISH]]<>"","CLOSE", IF(Tbl_SM[[#This Row],[ACTUAL START]]<>"","ON PROGRESS", "OPEN"))) -> OPEN | O17: =IF(Tbl_SM[[#This Row],[PLAN START]]="","", IF(Tbl_SM[[#This Row],[ACTUAL FINISH]]<>"","CLOSE", IF(TODAY()>Tbl_SM[[#This Row],[DUE DATA]],"OVERDUE", IF((Tbl_SM[[#This Row],[DUE DATA]]-TODAY())<=3,"< 3 HARI", IF((Tbl_SM[[#This Row],[DUE DATA]]-TODAY())<=7,"< 7 HARI", IF((Tbl_SM[[#This Row],[DUE DATA]]-TODAY())<=14,"< 14 HARI", "> 14 HARI")))))) -> > 14 HARI | P17: =IF(SUM(S17:AW17)=0,"",IFERROR(MAX(DG17:EK17),"")) -> 0.52666667 | Q17: =IF(Tbl_SM[[#This Row],[STATUS]]="CLOSE",1,0) -> 0 | S17: 0.05 | T17: 0.08 | U17: 0.1 | V17: 0.12666667 | W17: 0.15166667 | X17: 0.17666667 | Y17: 0.20166667 | Z17: 0.22666667 | AA17: 0.25166667 | AB17: 0.27666667 | AC17: 0.30166667 | AD17: 0.32666667 | AE17: 0.35166667 | AF17: 0.37666667 | AG17: 0.40166667 | AH17: 0.42666667 | AI17: 0.45166667 | AJ17: 0.47666667 | AK17: 0.50166667 | AL17: 0.50166667 | AM17: 0.50166667 | AN17: 0.50166667 | AO17: 0.50166667 | AP17: 0.50166667 | AQ17: 0.50166667 | AR17: 0.50166667 | AS17: 0.50166667 | AT17: 0.50166667 | AU17: 0.51 | AV17: 0.51833333 | AW17: 0.52666667 | AX17: 0.535 | AY17: 0.54333333 | AZ17: 0.55166667 | BA17: 0.56 | BB17: 0.56833333 | BC17: 0.6 | BD17: 0.63 | BE17: 0.66 | BF17: 0.69 | BG17: 0.72 | BH17: 0.75 | BI17: 0.78 | BJ17: 0.81 | BK17: 0.84 | BL17: 0.87 | BM17: 0.9 | BN17: 0.93 | BO17: 0.96 | BP17: 0.99 | BQ17: 1 | BR17: 1 | BS17: 1 | BT17: 1 | BU17: 1 | BV17: 1 | BW17: 1 | BX17: 1 | BY17: 1 | BZ17: 1 | CA17: 1 | CB17: 1 | CC17: 1 | CD17: 1 | CE17: 1 | CF17: 1 | CG17: 1 | CH17: 1 | CI17: 1 | CJ17: 1 | CK17: 1 | CL17: 1 | CM17: 1 | CN17: 1 | CO17: 1 | CP17: 1 | CQ17: 1 | CR17: 1 | CS17: 1 | CT17: 1 | CU17: 1 | CV17: 1 | CW17: 1 | CX17: 1 | CY17: 1 | CZ17: 1 | DA17: 1 | DB17: 1 | DC17: 1 | DD17: 1 | DE17: 1 | DG17: 0.05 | DH17: 0.08 | DI17: 0.1 | DJ17: 0.12666667 | DK17: 0.15166667 | DL17: 0.17666667 | DM17: 0.20166667 | DN17: 0.22666667 | DO17: 0.25166667 | DP17: 0.27666667 | DQ17: 0.30166667 | DR17: 0.32666667 | DS17: 0.35166667 | DT17: 0.37666667 | DU17: 0.40166667 | DV17: 0.42666667 | DW17: 0.45166667 | DX17: 0.47666667 | DY17: 0.50166667 | DZ17: 0.50166667 | EA17: 0.50166667 | EB17: 0.50166667 | EC17: 0.50166667 | ED17: 0.50166667 | EE17: 0.50166667 | EF17: 0.50166667 | EG17: 0.50166667 | EH17: 0.50166667 | EI17: 0.51 | EJ17: 0.51833333 | EK17: 0.52666667 | EL17: 0.535 | EM17: 0.54333333 | EN17: 0.55166667 | EO17: 0.56 | EP17: 0.56833333 | EQ17: 0.6 | ER17: 0.63 | ES17: 0.66 | ET17: 0.69 | EU17: 0.72 | EV17: 0.75 | EW17: 0.78 | EX17: 0.81 | EY17: 0.84 | EZ17: 0.87 | FA17: 0.9 | FB17: 0.93 | FC17: 0.96 | FD17: 0.99 | FE17: 1 | FF17: 1 | FG17: 1 | FH17: 1 | FI17: 1 | FJ17: 1 | FK17: 1 | FL17: 1 | FM17: 1 | FN17: 1 | FO17: 1 | FP17: 1 | FQ17: 1 | FR17: 1 | FS17: 1 | FT17: 1 | FU17: 1 | FV17: 1 | FW17: 1 | FX17: 1 | FY17: 1 | FZ17: 1 | GA17: 1 | GB17: 1 | GC17: 1 | GD17: 1 | GE17: 1 | GF17: 1 | GG17: 1 | GH17: 1 | GI17: 1 | GJ17: 1 | GK17: 1 | GL17: 1 | GM17: 1 | GN17: 1 | GO17: 1 | GP17: 1 | GQ17: 1 | GR17: 1 | GS17: 1 | GU17: =IF(AND(OR(S17="",S17=0),OR(DG17="",DG17=0)),"", MIN(1.2, IFERROR(DG17/IF(OR(S17="",S17=0),1,S17),0))) -> 1 | GV17: =IF(AND(OR(T17="",T17=0),OR(DH17="",DH17=0)),"", MIN(1.2, IFERROR(DH17/IF(OR(T17="",T17=0),1,T17),0))) -> 1 | GW17: =IF(AND(OR(U17="",U17=0),OR(DI17="",DI17=0)),"", MIN(1.2, IFERROR(DI17/IF(OR(U17="",U17=0),1,U17),0))) -> 1 | GX17: =IF(AND(OR(V17="",V17=0),OR(DJ17="",DJ17=0)),"", MIN(1.2, IFERROR(DJ17/IF(OR(V17="",V17=0),1,V17),0))) -> 1 | GY17: =IF(AND(OR(W17="",W17=0),OR(DK17="",DK17=0)),"", MIN(1.2, IFERROR(DK17/IF(OR(W17="",W17=0),1,W17),0))) -> 1 | GZ17: =IF(AND(OR(X17="",X17=0),OR(DL17="",DL17=0)),"", MIN(1.2, IFERROR(DL17/IF(OR(X17="",X17=0),1,X17),0))) -> 1 | HA17: =IF(AND(OR(Y17="",Y17=0),OR(DM17="",DM17=0)),"", MIN(1.2, IFERROR(DM17/IF(OR(Y17="",Y17=0),1,Y17),0))) -> 1 | HB17: =IF(AND(OR(Z17="",Z17=0),OR(DN17="",DN17=0)),"", MIN(1.2, IFERROR(DN17/IF(OR(Z17="",Z17=0),1,Z17),0))) -> 1 | ... KG17: =IF(AND(OR(DE17="",DE17=0),OR(GS17="",GS17=0)),"", MIN(1.2, IFERROR(GS17/IF(OR(DE17="",DE17=0),1,DE17),0))) -> 1
B18: 11 | C18: METHOD | D18: Jadwal PM bentrok dengan kebutuhan operasi sehingga PM tertunda. | E18: Quick Action | F18: Susun weekly maintenance window dan koordinasi unit replacement dengan user. | G18: GS-PLANT-USER | H18: 46188 | I18: 46199 | J18: =(I18-H18)+1 -> 12 | M18: =IF(AND(K18=0,L18=0),"No Progress",IF(Tbl_SM[[#This Row],[ACTUAL START]]="",0,IF(L18-K18<0,"On Progress",L18-K18))) -> No Progress | N18: =IF(Tbl_SM[[#This Row],[PLAN START]]="","", IF(Tbl_SM[[#This Row],[ACTUAL FINISH]]<>"","CLOSE", IF(Tbl_SM[[#This Row],[ACTUAL START]]<>"","ON PROGRESS", "OPEN"))) -> OPEN | O18: =IF(Tbl_SM[[#This Row],[PLAN START]]="","", IF(Tbl_SM[[#This Row],[ACTUAL FINISH]]<>"","CLOSE", IF(TODAY()>Tbl_SM[[#This Row],[DUE DATA]],"OVERDUE", IF((Tbl_SM[[#This Row],[DUE DATA]]-TODAY())<=3,"< 3 HARI", IF((Tbl_SM[[#This Row],[DUE DATA]]-TODAY())<=7,"< 7 HARI", IF((Tbl_SM[[#This Row],[DUE DATA]]-TODAY())<=14,"< 14 HARI", "> 14 HARI")))))) -> > 14 HARI | P18: =IF(SUM(S18:AW18)=0,"",IFERROR(MAX(DG18:EK18),"")) -> 0.52666667 | Q18: =IF(Tbl_SM[[#This Row],[STATUS]]="CLOSE",1,0) -> 0 | S18: 0.05 | T18: 0.08 | U18: 0.1 | V18: 0.12666667 | W18: 0.15166667 | X18: 0.17666667 | Y18: 0.20166667 | Z18: 0.22666667 | AA18: 0.25166667 | AB18: 0.27666667 | AC18: 0.30166667 | AD18: 0.32666667 | AE18: 0.35166667 | AF18: 0.37666667 | AG18: 0.40166667 | AH18: 0.42666667 | AI18: 0.45166667 | AJ18: 0.47666667 | AK18: 0.50166667 | AL18: 0.50166667 | AM18: 0.50166667 | AN18: 0.50166667 | AO18: 0.50166667 | AP18: 0.50166667 | AQ18: 0.50166667 | AR18: 0.50166667 | AS18: 0.50166667 | AT18: 0.50166667 | AU18: 0.51 | AV18: 0.51833333 | AW18: 0.52666667 | AX18: 0.535 | AY18: 0.54333333 | AZ18: 0.55166667 | BA18: 0.56 | BB18: 0.56833333 | BC18: 0.6 | BD18: 0.63 | BE18: 0.66 | BF18: 0.69 | BG18: 0.72 | BH18: 0.75 | BI18: 0.78 | BJ18: 0.81 | BK18: 0.84 | BL18: 0.87 | BM18: 0.9 | BN18: 0.93 | BO18: 0.96 | BP18: 0.99 | BQ18: 1 | BR18: 1 | BS18: 1 | BT18: 1 | BU18: 1 | BV18: 1 | BW18: 1 | BX18: 1 | BY18: 1 | BZ18: 1 | CA18: 1 | CB18: 1 | CC18: 1 | CD18: 1 | CE18: 1 | CF18: 1 | CG18: 1 | CH18: 1 | CI18: 1 | CJ18: 1 | CK18: 1 | CL18: 1 | CM18: 1 | CN18: 1 | CO18: 1 | CP18: 1 | CQ18: 1 | CR18: 1 | CS18: 1 | CT18: 1 | CU18: 1 | CV18: 1 | CW18: 1 | CX18: 1 | CY18: 1 | CZ18: 1 | DA18: 1 | DB18: 1 | DC18: 1 | DD18: 1 | DE18: 1 | DG18: 0.05 | DH18: 0.08 | DI18: 0.1 | DJ18: 0.12666667 | DK18: 0.15166667 | DL18: 0.17666667 | DM18: 0.20166667 | DN18: 0.22666667 | DO18: 0.25166667 | DP18: 0.27666667 | DQ18: 0.30166667 | DR18: 0.32666667 | DS18: 0.35166667 | DT18: 0.37666667 | DU18: 0.40166667 | DV18: 0.42666667 | DW18: 0.45166667 | DX18: 0.47666667 | DY18: 0.50166667 | DZ18: 0.50166667 | EA18: 0.50166667 | EB18: 0.50166667 | EC18: 0.50166667 | ED18: 0.50166667 | EE18: 0.50166667 | EF18: 0.50166667 | EG18: 0.50166667 | EH18: 0.50166667 | EI18: 0.51 | EJ18: 0.51833333 | EK18: 0.52666667 | EL18: 0.535 | EM18: 0.54333333 | EN18: 0.55166667 | EO18: 0.56 | EP18: 0.56833333 | EQ18: 0.6 | ER18: 0.63 | ES18: 0.66 | ET18: 0.69 | EU18: 0.72 | EV18: 0.75 | EW18: 0.78 | EX18: 0.81 | EY18: 0.84 | EZ18: 0.87 | FA18: 0.9 | FB18: 0.93 | FC18: 0.96 | FD18: 0.99 | FE18: 1 | FF18: 1 | FG18: 1 | FH18: 1 | FI18: 1 | FJ18: 1 | FK18: 1 | FL18: 1 | FM18: 1 | FN18: 1 | FO18: 1 | FP18: 1 | FQ18: 1 | FR18: 1 | FS18: 1 | FT18: 1 | FU18: 1 | FV18: 1 | FW18: 1 | FX18: 1 | FY18: 1 | FZ18: 1 | GA18: 1 | GB18: 1 | GC18: 1 | GD18: 1 | GE18: 1 | GF18: 1 | GG18: 1 | GH18: 1 | GI18: 1 | GJ18: 1 | GK18: 1 | GL18: 1 | GM18: 1 | GN18: 1 | GO18: 1 | GP18: 1 | GQ18: 1 | GR18: 1 | GS18: 1 | GU18: =IF(AND(OR(S18="",S18=0),OR(DG18="",DG18=0)),"", MIN(1.2, IFERROR(DG18/IF(OR(S18="",S18=0),1,S18),0))) -> 1 | GV18: =IF(AND(OR(T18="",T18=0),OR(DH18="",DH18=0)),"", MIN(1.2, IFERROR(DH18/IF(OR(T18="",T18=0),1,T18),0))) -> 1 | GW18: =IF(AND(OR(U18="",U18=0),OR(DI18="",DI18=0)),"", MIN(1.2, IFERROR(DI18/IF(OR(U18="",U18=0),1,U18),0))) -> 1 | GX18: =IF(AND(OR(V18="",V18=0),OR(DJ18="",DJ18=0)),"", MIN(1.2, IFERROR(DJ18/IF(OR(V18="",V18=0),1,V18),0))) -> 1 | GY18: =IF(AND(OR(W18="",W18=0),OR(DK18="",DK18=0)),"", MIN(1.2, IFERROR(DK18/IF(OR(W18="",W18=0),1,W18),0))) -> 1 | GZ18: =IF(AND(OR(X18="",X18=0),OR(DL18="",DL18=0)),"", MIN(1.2, IFERROR(DL18/IF(OR(X18="",X18=0),1,X18),0))) -> 1 | HA18: =IF(AND(OR(Y18="",Y18=0),OR(DM18="",DM18=0)),"", MIN(1.2, IFERROR(DM18/IF(OR(Y18="",Y18=0),1,Y18),0))) -> 1 | HB18: =IF(AND(OR(Z18="",Z18=0),OR(DN18="",DN18=0)),"", MIN(1.2, IFERROR(DN18/IF(OR(Z18="",Z18=0),1,Z18),0))) -> 1 | ... KG18: =IF(AND(OR(DE18="",DE18=0),OR(GS18="",GS18=0)),"", MIN(1.2, IFERROR(GS18/IF(OR(DE18="",DE18=0),1,DE18),0))) -> 1
B19: 12 | C19: MACHINE | D19: Sebagian LV memiliki health score rendah akibat usia pakai dan backlog repair. | E19: Quick Action | F19: Mapping health condition: fit, monitor, restricted, stop use; buat recovery plan per unit. | G19: GS-PLANT | H19: 46181 | I19: 46206 | J19: =(I19-H19)+1 -> 26 | M19: =IF(AND(K19=0,L19=0),"No Progress",IF(Tbl_SM[[#This Row],[ACTUAL START]]="",0,IF(L19-K19<0,"On Progress",L19-K19))) -> No Progress | N19: =IF(Tbl_SM[[#This Row],[PLAN START]]="","", IF(Tbl_SM[[#This Row],[ACTUAL FINISH]]<>"","CLOSE", IF(Tbl_SM[[#This Row],[ACTUAL START]]<>"","ON PROGRESS", "OPEN"))) -> OPEN | O19: =IF(Tbl_SM[[#This Row],[PLAN START]]="","", IF(Tbl_SM[[#This Row],[ACTUAL FINISH]]<>"","CLOSE", IF(TODAY()>Tbl_SM[[#This Row],[DUE DATA]],"OVERDUE", IF((Tbl_SM[[#This Row],[DUE DATA]]-TODAY())<=3,"< 3 HARI", IF((Tbl_SM[[#This Row],[DUE DATA]]-TODAY())<=7,"< 7 HARI", IF((Tbl_SM[[#This Row],[DUE DATA]]-TODAY())<=14,"< 14 HARI", "> 14 HARI")))))) -> > 14 HARI | P19: =IF(SUM(S19:AW19)=0,"",IFERROR(MAX(DG19:EK19),"")) -> 0.52666667 | Q19: =IF(Tbl_SM[[#This Row],[STATUS]]="CLOSE",1,0) -> 0 | S19: 0.05 | T19: 0.08 | U19: 0.1 | V19: 0.12666667 | W19: 0.15166667 | X19: 0.17666667 | Y19: 0.20166667 | Z19: 0.22666667 | AA19: 0.25166667 | AB19: 0.27666667 | AC19: 0.30166667 | AD19: 0.32666667 | AE19: 0.35166667 | AF19: 0.37666667 | AG19: 0.40166667 | AH19: 0.42666667 | AI19: 0.45166667 | AJ19: 0.47666667 | AK19: 0.50166667 | AL19: 0.50166667 | AM19: 0.50166667 | AN19: 0.50166667 | AO19: 0.50166667 | AP19: 0.50166667 | AQ19: 0.50166667 | AR19: 0.50166667 | AS19: 0.50166667 | AT19: 0.50166667 | AU19: 0.51 | AV19: 0.51833333 | AW19: 0.52666667 | AX19: 0.535 | AY19: 0.54333333 | AZ19: 0.55166667 | BA19: 0.56 | BB19: 0.56833333 | BC19: 0.6 | BD19: 0.63 | BE19: 0.66 | BF19: 0.69 | BG19: 0.72 | BH19: 0.75 | BI19: 0.78 | BJ19: 0.81 | BK19: 0.84 | BL19: 0.87 | BM19: 0.9 | BN19: 0.93 | BO19: 0.96 | BP19: 0.99 | BQ19: 1 | BR19: 1 | BS19: 1 | BT19: 1 | BU19: 1 | BV19: 1 | BW19: 1 | BX19: 1 | BY19: 1 | BZ19: 1 | CA19: 1 | CB19: 1 | CC19: 1 | CD19: 1 | CE19: 1 | CF19: 1 | CG19: 1 | CH19: 1 | CI19: 1 | CJ19: 1 | CK19: 1 | CL19: 1 | CM19: 1 | CN19: 1 | CO19: 1 | CP19: 1 | CQ19: 1 | CR19: 1 | CS19: 1 | CT19: 1 | CU19: 1 | CV19: 1 | CW19: 1 | CX19: 1 | CY19: 1 | CZ19: 1 | DA19: 1 | DB19: 1 | DC19: 1 | DD19: 1 | DE19: 1 | DG19: 0.05 | DH19: 0.08 | DI19: 0.1 | DJ19: 0.12666667 | DK19: 0.15166667 | DL19: 0.17666667 | DM19: 0.20166667 | DN19: 0.22666667 | DO19: 0.25166667 | DP19: 0.27666667 | DQ19: 0.30166667 | DR19: 0.32666667 | DS19: 0.35166667 | DT19: 0.37666667 | DU19: 0.40166667 | DV19: 0.42666667 | DW19: 0.45166667 | DX19: 0.47666667 | DY19: 0.50166667 | DZ19: 0.50166667 | EA19: 0.50166667 | EB19: 0.50166667 | EC19: 0.50166667 | ED19: 0.50166667 | EE19: 0.50166667 | EF19: 0.50166667 | EG19: 0.50166667 | EH19: 0.50166667 | EI19: 0.51 | EJ19: 0.51833333 | EK19: 0.52666667 | EL19: 0.535 | EM19: 0.54333333 | EN19: 0.55166667 | EO19: 0.56 | EP19: 0.56833333 | EQ19: 0.6 | ER19: 0.63 | ES19: 0.66 | ET19: 0.69 | EU19: 0.72 | EV19: 0.75 | EW19: 0.78 | EX19: 0.81 | EY19: 0.84 | EZ19: 0.87 | FA19: 0.9 | FB19: 0.93 | FC19: 0.96 | FD19: 0.99 | FE19: 1 | FF19: 1 | FG19: 1 | FH19: 1 | FI19: 1 | FJ19: 1 | FK19: 1 | FL19: 1 | FM19: 1 | FN19: 1 | FO19: 1 | FP19: 1 | FQ19: 1 | FR19: 1 | FS19: 1 | FT19: 1 | FU19: 1 | FV19: 1 | FW19: 1 | FX19: 1 | FY19: 1 | FZ19: 1 | GA19: 1 | GB19: 1 | GC19: 1 | GD19: 1 | GE19: 1 | GF19: 1 | GG19: 1 | GH19: 1 | GI19: 1 | GJ19: 1 | GK19: 1 | GL19: 1 | GM19: 1 | GN19: 1 | GO19: 1 | GP19: 1 | GQ19: 1 | GR19: 1 | GS19: 1 | GU19: =IF(AND(OR(S19="",S19=0),OR(DG19="",DG19=0)),"", MIN(1.2, IFERROR(DG19/IF(OR(S19="",S19=0),1,S19),0))) -> 1 | GV19: =IF(AND(OR(T19="",T19=0),OR(DH19="",DH19=0)),"", MIN(1.2, IFERROR(DH19/IF(OR(T19="",T19=0),1,T19),0))) -> 1 | GW19: =IF(AND(OR(U19="",U19=0),OR(DI19="",DI19=0)),"", MIN(1.2, IFERROR(DI19/IF(OR(U19="",U19=0),1,U19),0))) -> 1 | GX19: =IF(AND(OR(V19="",V19=0),OR(DJ19="",DJ19=0)),"", MIN(1.2, IFERROR(DJ19/IF(OR(V19="",V19=0),1,V19),0))) -> 1 | GY19: =IF(AND(OR(W19="",W19=0),OR(DK19="",DK19=0)),"", MIN(1.2, IFERROR(DK19/IF(OR(W19="",W19=0),1,W19),0))) -> 1 | GZ19: =IF(AND(OR(X19="",X19=0),OR(DL19="",DL19=0)),"", MIN(1.2, IFERROR(DL19/IF(OR(X19="",X19=0),1,X19),0))) -> 1 | HA19: =IF(AND(OR(Y19="",Y19=0),OR(DM19="",DM19=0)),"", MIN(1.2, IFERROR(DM19/IF(OR(Y19="",Y19=0),1,Y19),0))) -> 1 | HB19: =IF(AND(OR(Z19="",Z19=0),OR(DN19="",DN19=0)),"", MIN(1.2, IFERROR(DN19/IF(OR(Z19="",Z19=0),1,Z19),0))) -> 1 | ... KG19: =IF(AND(OR(DE19="",DE19=0),OR(GS19="",GS19=0)),"", MIN(1.2, IFERROR(GS19/IF(OR(DE19="",DE19=0),1,DE19),0))) -> 1
